Workbook

Sheet הגדרות
A1: הגדרות ופרמטרים – AI & Business Tools Expenses
A3: שער חליפין
A4: שער USD → ILS (מתעדכן אוטומטית) | B4: 2.962 | C4: ← מקור: Bank of Israel Public API | עודכן: 2026-05-04
A6: הערה: | B6: כל הסכומים בשקלים מחושבים על פי השיעור שמוגדר בתא B4. ניתן לשנות שיעור זה לפי השיעור היסטורי הרצוי. שיעורי ההמרה בפועל ששולמו עשויים להיות שונים מעט בשל עמלות המרה.
A10: חיובים קבועים: | B10: OpenAI / ChatGPT Plus – $20 בכל 16 לחודש. החיוב מתווסף אוטומטית לכל חודש בדוחות, בגליונות ובדשבורד, וכאשר תגיע חשבונית OpenAI במייל היא אמורה להיות מזוהה תחת אותו כלי.

Sheet כל ההוצאות
A1: כל ההוצאות – כלי AI | יולי 2025 – דצמבר 2026
A2: תאריך | B2: כלי | C2: תיאור | D2: סכום ($) | E2: סכום (₪) | F2: חודש
A3: 2025-07-04 | B3: Recraft | C3: Basic – first month promo | D3: 1.127616 | E3: 3.34 | F3: יולי 2025
A4: 2025-07-09 | B4: Ideogram AI | C4: Ideogram Basic – annual | D4: 81.390952 | E4: 241.08 | F4: יולי 2025
A5: 2025-07-10 | B5: Make | C5: Core plan 10k ops/month | D5: 11.829845 | E5: 35.04 | F5: יולי 2025
A6: 2025-07-11 | B6: Anthropic | C6: Claude Pro | D6: 22.383525 | E6: 66.3 | F6: יולי 2025
A7: 2025-07-16 | B7: OpenAI | C7: ChatGPT Plus | D7: 20 | E7: 67.31 | F7: יולי 2025
A8: 2025-07-20 | B8: Runway ML | C8: Standard (10% affiliate off) | D8: 15.303849 | E8: 45.33 | F8: יולי 2025
A9: 2025-07-30 | B9: Ideogram AI | C9: Upgrade -> Plus Annual | D9: 128.58204 | E9: 380.86 | F9: יולי 2025
A10: 2025-07-30 | B10: Replicate | C10: Early card charge | D10: 11.363943 | E10: 33.66 | F10: יולי 2025
A11: 2025-08-01 | B11: Google Workspace | C11: Business Plus – Jul 2025 (₪56.93) | D11: 19.220122 | E11: 56.93 | F11: אוגוסט 2025
A12: 2025-08-02 | B12: Runway ML | C12: Credits 1,500 | D12: 17.282242 | E12: 51.19 | F12: אוגוסט 2025
A13: 2025-08-04 | B13: Recraft | C13: Basic monthly | D13: 13.81499 | E13: 40.92 | F13: אוגוסט 2025
A14: 2025-08-05 | B14: Replicate | C14: Usage - July | D14: 1.039838 | E14: 3.08 | F14: אוגוסט 2025
... A133: 2026-12-16 | B133: OpenAI | C133: ChatGPT Plus | D133: 20 | E133: 73 | F133: דצמבר 2026
A134: סה"כ" | D134: =SUM(D3:D133) | E134: =SUM(E3:E133)

Sheet יולי 2025
A1: יולי 2025 | July 2025
A2: ← חזרה לסיכום חודשי
A3: תאריך | B3: כלי | C3: תיאור | D3: סכום ($) | E3: סכום (₪)
A4: 2025-07-04 | B4: Recraft | C4: Basic – first month promo | D4: 1.127616 | E4: 3.34
A5: 2025-07-09 | B5: Ideogram AI | C5: Ideogram Basic – annual | D5: 81.390952 | E5: 241.08
A6: 2025-07-10 | B6: Make | C6: Core plan 10k ops/month | D6: 11.829845 | E6: 35.04
A7: 2025-07-11 | B7: Anthropic | C7: Claude Pro | D7: 22.383525 | E7: 66.3
A8: 2025-07-16 | B8: OpenAI | C8: ChatGPT Plus | D8: 20 | E8: 67.31
A9: 2025-07-20 | B9: Runway ML | C9: Standard (10% affiliate off) | D9: 15.303849 | E9: 45.33
A10: 2025-07-30 | B10: Ideogram AI | C10: Upgrade -> Plus Annual | D10: 128.58204 | E10: 380.86
A11: 2025-07-30 | B11: Replicate | C11: Early card charge | D11: 11.363943 | E11: 33.66
A12: סה"כ חודש" | D12: =SUM(D4:D11) | E12: =SUM(E4:E11)

Sheet אוגוסט 2025
A1: אוגוסט 2025 | August 2025
A2: ← חזרה לסיכום חודשי
A3: תאריך | B3: כלי | C3: תיאור | D3: סכום ($) | E3: סכום (₪)
A4: 2025-08-01 | B4: Google Workspace | C4: Business Plus – Jul 2025 (₪56.93) | D4: 19.220122 | E4: 56.93
A5: 2025-08-02 | B5: Runway ML | C5: Credits 1,500 | D5: 17.282242 | E5: 51.19
A6: 2025-08-04 | B6: Recraft | C6: Basic monthly | D6: 13.81499 | E6: 40.92
A7: 2025-08-05 | B7: Replicate | C7: Usage - July | D7: 1.039838 | E7: 3.08
A8: 2025-08-09 | B8: Manus AI | C8: Basic monthly | D8: 22.025658 | E8: 65.24
A9: 2025-08-10 | B9: Make | C9: Core plan 10k ops/month | D9: 12.27549 | E9: 36.36
A10: 2025-08-11 | B10: Anthropic | C10: Claude Pro | D10: 23.102633 | E10: 68.43
A11: 2025-08-16 | B11: OpenAI | C11: ChatGPT Plus | D11: 20 | E11: 67.54
A12: 2025-08-30 | B12: Eleven Labs | C12: Starter monthly | D12: 5.641458 | E12: 16.71
A13: 2025-08-30 | B13: Runway ML | C13: Standard (25% off) | D13: 12.694126 | E13: 37.6
A14: סה"כ חודש" | D14: =SUM(D4:D13) | E14: =SUM(E4:E13)

Sheet ספטמבר 2025
A1: ספטמבר 2025 | September 2025
A2: ← חזרה לסיכום חודשי
A3: תאריך | B3: כלי | C3: תיאור | D3: סכום ($) | E3: סכום (₪)
A4: 2025-09-01 | B4: Google Workspace | C4: Business Plus – Aug 2025 (₪56.93) | D4: 19.220122 | E4: 56.93
A5: 2025-09-05 | B5: Replicate | C5: Usage - August | D5: 3.153275 | E5: 9.34
A6: 2025-09-10 | B6: Make | C6: Core plan 10k ops/month | D6: 11.95476 | E6: 35.41
A7: 2025-09-16 | B7: OpenAI | C7: ChatGPT Plus | D7: 20 | E7: 67.01
A8: 2025-09-24 | B8: Anthropic | C8: Claude Pro | D8: 22.572586 | E8: 66.86
A9: 2025-09-30 | B9: Eleven Labs | C9: Starter monthly | D9: 5.573937 | E9: 16.51
A10: סה"כ חודש" | D10: =SUM(D4:D9) | E10: =SUM(E4:E9)

Sheet אוקטובר 2025
A1: אוקטובר 2025 | October 2025
A2: ← חזרה לסיכום חודשי
A3: תאריך | B3: כלי | C3: תיאור | D3: סכום ($) | E3: סכום (₪)
A4: 2025-10-02 | B4: Google Workspace | C4: Business Plus – Sep 2025 (₪56.93) | D4: 19.220122 | E4: 56.93
A5: 2025-10-16 | B5: OpenAI | C5: ChatGPT Plus | D5: 20 | E5: 65.72
A6: 2025-10-24 | B6: Anthropic | C6: Claude Pro | D6: 22.21472 | E6: 65.8
A7: 2025-10-30 | B7: Eleven Labs | C7: Starter monthly | D7: 5.49291 | E7: 16.27
A8: סה"כ חודש" | D8: =SUM(D4:D7) | E8: =SUM(E4:E7)

Sheet נובמבר 2025
A1: נובמבר 2025 | November 2025
A2: ← חזרה לסיכום חודשי
A3: תאריך | B3: כלי | C3: תיאור | D3: סכום ($) | E3: סכום (₪)
A4: 2025-11-09 | B4: Recraft | C4: Pro 1k credits | D4: 13.207292 | E4: 39.12
A5: 2025-11-11 | B5: Astria | C5: Credits x10 + 18% VAT | D5: 12.86293 | E5: 38.1
A6: 2025-11-11 | B6: Runway ML | C6: Standard monthly | D6: 16.353815 | E6: 48.44
A7: 2025-11-13 | B7: Hedra | C7: Extra Small Credit Pack | D7: 10.786631 | E7: 31.95
A8: 2025-11-16 | B8: OpenAI | C8: ChatGPT Plus | D8: 20 | E8: 64.68
A9: 2025-11-24 | B9: Anthropic | C9: Claude Pro | D9: 22.120189 | E9: 65.52
A10: 2025-11-30 | B10: Eleven Labs | C10: Starter monthly | D10: 5.506415 | E10: 16.31
A11: סה"כ חודש" | D11: =SUM(D4:D10) | E11: =SUM(E4:E10)

Sheet דצמבר 2025
A1: דצמבר 2025 | December 2025
A2: ← חזרה לסיכום חודשי
A3: תאריך | B3: כלי | C3: תיאור | D3: סכום ($) | E3: סכום (₪)
A4: 2025-12-01 | B4: Google Workspace | C4: Business Plus – Nov 2025 (₪75.90) | D4: 25.624578 | E4: 75.9
A5: 2025-12-03 | B5: Manychat | C5: Pro monthly | D5: 16.468602 | E5: 48.78
A6: 2025-12-03 | B6: Meta (Ads) | C6: Facebook Ads | D6: 10.671843 | E6: 31.61
A7: 2025-12-08 | B7: Meta (Ads) | C7: Facebook Ads | D7: 32.734639 | E7: 96.96
A8: 2025-12-16 | B8: Meta (Ads) | C8: Facebook Ads | D8: 35.796759 | E8: 106.03
A9: 2025-12-16 | B9: OpenAI | C9: ChatGPT Plus | D9: 20 | E9: 64.26
A10: 2025-12-29 | B10: Meta (Ads) | C10: Facebook Ads | D10: 38.760972 | E10: 114.81
A11: 2025-12-30 | B11: Eleven Labs | C11: Starter monthly | D11: 5.378123 | E11: 15.93
A12: סה"כ חודש" | D12: =SUM(D4:D11) | E12: =SUM(E4:E11)

Sheet ינואר 2026
A1: ינואר 2026 | January 2026
A2: ← חזרה לסיכום חודשי
A3: תאריך | B3: כלי | C3: תיאור | D3: סכום ($) | E3: סכום (₪)
A4: 2026-01-01 | B4: Google Workspace | C4: Business Plus – Dec 2025 (₪75.90) | D4: 25.624578 | E4: 75.9
A5: 2026-01-03 | B5: Genspark | C5: Plus Annual (happynewyear26 promo) | D5: 150.48278 | E5: 445.73
A6: 2026-01-03 | B6: Manychat | C6: Pro monthly | D6: 16.130993 | E6: 47.78
A7: 2026-01-03 | B7: Meta (Ads) | C7: Facebook Ads | D7: 20.898042 | E7: 61.9
A8: 2026-01-05 | B8: Genspark | C8: Credits Pack | D8: 21.441594 | E8: 63.51
A9: 2026-01-08 | B9: Genspark | C9: Credits Pack | D9: 21.380824 | E9: 63.33
A10: 2026-01-10 | B10: CapCut | C10: Pro – Jan 2026 (₪49.90) | D10: 16.846725 | E10: 49.9
A11: 2026-01-16 | B11: OpenAI | C11: ChatGPT Plus | D11: 20 | E11: 62.81
A12: 2026-01-19 | B12: Meta (Ads) | C12: Facebook Ads | D12: 41.458474 | E12: 122.8
A13: 2026-01-25 | B13: Lovable | C13: Pro 1 monthly | D13: 26.404456 | E13: 78.21
A14: 2026-01-27 | B14: Meta (Ads) | C14: Facebook Ads | D14: 45.239703 | E14: 134
A15: 2026-01-30 | B15: Eleven Labs | C15: Starter monthly | D15: 5.209318 | E15: 15.43
A16: 2026-01-30 | B16: Timeless | C16: Pro monthly (50% off) | D16: 15.104659 | E16: 44.74
A17: סה"כ חודש" | D17: =SUM(D4:D16) | E17: =SUM(E4:E16)

Sheet פברואר 2026
A1: פברואר 2026 | February 2026
A2: ← חזרה לסיכום חודשי
A3: תאריך | B3: כלי | C3: תיאור | D3: סכום ($) | E3: סכום (₪)
A4: 2026-02-01 | B4: Lovable | C4: Upgrade Pro1 -> Pro2 (prorated) | D4: 26.18501 | E4: 77.56
A5: 2026-02-02 | B5: Google Workspace | C5: Business Plus – Jan 2026 (₪75.90) | D5: 25.624578 | E5: 75.9
A6: 2026-02-03 | B6: Meta (Ads) | C6: Facebook Ads | D6: 32.873059 | E6: 97.37
A7: 2026-02-10 | B7: CapCut | C7: Pro – Feb 2026 (₪49.90) | D7: 16.846725 | E7: 49.9
A8: 2026-02-12 | B8: Meta (Ads) | C8: Facebook Ads | D8: 48.825118 | E8: 144.62
A9: 2026-02-15 | B9: Anthropic | C9: Claude Pro | D9: 20.840648 | E9: 61.73
A10: 2026-02-16 | B10: Anthropic | C10: Credit purchase | D10: 5.212694 | E10: 15.44
A11: 2026-02-16 | B11: OpenAI | C11: ChatGPT Plus | D11: 20 | E11: 61.77
A12: 2026-02-24 | B12: Higgsfield | C12: On-Demand credits 500 | D12: 21.120864 | E12: 62.56
A13: 2026-02-25 | B13: Lovable | C13: Pro2 monthly | D13: 52.316003 | E13: 154.96
A14: 2026-02-25 | B14: Meta (Ads) | C14: Facebook Ads | D14: 53.362593 | E14: 158.06
A15: 2026-02-28 | B15: Eleven Labs | C15: Starter monthly | D15: 5.29372 | E15: 15.68
A16: 2026-02-28 | B16: Lovable | C16: Cloud & AI Balance Top-up | D16: 10.584065 | E16: 31.35
A17: סה"כ חודש" | D17: =SUM(D4:D16) | E17: =SUM(E4:E16)

Sheet מרץ 2026
A1: מרץ 2026 | March 2026
A2: ← חזרה לסיכום חודשי
A3: תאריך | B3: כלי | C3: תיאור | D3: סכום ($) | E3: סכום (₪)
A4: 2026-03-01 | B4: Google Workspace | C4: Google Workspace (₪75.9) | D4: 25.624578 | E4: 75.9
A5: 2026-03-01 | B5: Lovable | C5: Cloud & AI Balance Top-up | D5: 10.560432 | E5: 31.28
A6: 2026-03-01 | B6: Timeless | C6: Pro monthly (50% off) | D6: 15.313977 | E6: 45.36
A7: 2026-03-02 | B7: Google Workspace | C7: Business Plus – Feb 2026 (₪75.90) | D7: 25.624578 | E7: 75.9
A8: 2026-03-02 | B8: Lovable | C8: Cloud & AI Balance Top-up | D8: 10.533423 | E8: 31.2
A9: 2026-03-03 | B9: Meta (Ads) | C9: Facebook Ads | D9: 41.671168 | E9: 123.43
A10: 2026-03-10 | B10: CapCut | C10: Pro – Mar 2026 (₪49.90) | D10: 16.846725 | E10: 49.9
A11: 2026-03-12 | B11: Meta (Ads) | C11: Facebook Ads | D11: 53.906144 | E11: 159.67
A12: 2026-03-15 | B12: Anthropic | C12: Claude Pro | D12: 21.225523 | E12: 62.87
A13: 2026-03-16 | B13: OpenAI | C13: ChatGPT Plus | D13: 20 | E13: 62.87
A14: 2026-03-18 | B14: CapCut | C14: Pro – Mar 2026 (₪49.90) | D14: 16.846725 | E14: 49.9
A15: 2026-03-19 | B15: Anthropic | C15: Credit purchase | D15: 10.503038 | E15: 31.11
... A19: 2026-03-26 | B19: Dzine | C19: Video Top-Up | D19: 21.056718 | E19: 62.37
A20: סה"כ חודש" | D20: =SUM(D4:D19) | E20: =SUM(E4:E19)

Sheet אפריל 2026
A1: אפריל 2026 | April 2026
A2: ← חזרה לסיכום חודשי
A3: תאריך | B3: כלי | C3: תיאור | D3: סכום ($) | E3: סכום (₪)
A4: 2026-04-01 | B4: Anthropic | C4: Prepaid extra usage, Individual plan | D4: 10.61445 | E4: 31.44
A5: 2026-04-01 | B5: Google Workspace | C5: Business Plus – Mar 2026 (₪75.90) | D5: 25.624578 | E5: 75.9
A6: 2026-04-01 | B6: Meta (Ads) | C6: Facebook Ads | D6: 56.154625 | E6: 166.33
A7: 2026-04-02 | B7: Dzine | C7: Video Top-Up | D7: 19.071573 | E7: 56.49
A8: 2026-04-03 | B8: Meta (Ads) | C8: Facebook Ads | D8: 2.380149 | E8: 7.05
A9: 2026-04-05 | B9: IONOS | C9: Instant Domain | D9: 21.212019 | E9: 62.83
A10: 2026-04-10 | B10: CapCut | C10: capcut_pro_discount1 | D10: 16.846725 | E10: 49.9
A11: 2026-04-15 | B11: Anthropic | C11: Claude Pro | D11: 20 | E11: 60.19
A12: 2026-04-16 | B12: Anthropic | C12: Prepaid extra usage, Individual plan | D12: 10 | E12: 29.98
A13: 2026-04-16 | B13: OpenAI | C13: ChatGPT Plus | D13: 20 | E13: 59.96
A14: 2026-04-18 | B14: CapCut | C14: Pro – Apr 2026 (₪49.90) | D14: 16.846725 | E14: 49.9
A15: 2026-04-18 | B15: OpenAI | C15: ChatGPT Pro Subscription | D15: 81.141121 | E15: 240.34
... A31: 2026-04-28 | B31: Anthropic | C31: Auto recharge extra usage, Individual plan | D31: 10.56 | E31: 31.42
A32: סה"כ חודש" | D32: =SUM(D4:D31) | E32: =SUM(E4:E31)

Sheet מאי 2026
A1: מאי 2026 | May 2026
A2: ← חזרה לסיכום חודשי
A3: תאריך | B3: כלי | C3: תיאור | D3: סכום ($) | E3: סכום (₪)
A4: 2026-05-01 | B4: Anthropic | C4: Auto recharge extra usage, Individual plan | D4: 10.367995 | E4: 30.71
A5: 2026-05-01 | B5: Anthropic | C5: Auto recharge extra usage, Individual plan | D5: 10.806887 | E5: 32.01
A6: 2026-05-01 | B6: Anthropic | C6: Auto recharge extra usage, Individual plan | D6: 10.786631 | E6: 31.95
A7: 2026-05-01 | B7: Google Cloud | C7: Google Cloud Platform & APIs (₪8.23) | D7: 2.778528 | E7: 8.23
A8: 2026-05-01 | B8: Google Workspace | C8: Google Workspace (₪75.90) | D8: 25.624578 | E8: 75.9
A9: 2026-05-02 | B9: Anthropic | C9: Prepaid extra usage, Individual plan | D9: 4.976367 | E9: 14.74
A10: 2026-05-03 | B10: Anthropic | C10: Auto recharge extra usage, Individual plan | D10: 15.256583 | E10: 45.19
A11: 2026-05-03 | B11: Meta (Ads) | C11: Facebook Ads | D11: 27.150574 | E11: 80.42
A12: 2026-05-04 | B12: Anthropic | C12: Auto recharge extra usage, Individual plan | D12: 15.290344 | E12: 45.29
A13: 2026-05-04 | B13: Eleven Labs | C13: Creator monthly | D13: 21.863606 | E13: 64.76
A14: 2026-05-16 | B14: OpenAI | C14: ChatGPT Plus | D14: 20 | E14: 73
A15: סה"כ חודש" | D15: =SUM(D4:D14) | E15: =SUM(E4:E14)

Sheet יוני 2026
A1: יוני 2026 | June 2026
A2: ← חזרה לסיכום חודשי
A3: תאריך | B3: כלי | C3: תיאור | D3: סכום ($) | E3: סכום (₪)
A4: 2026-06-16 | B4: OpenAI | C4: ChatGPT Plus | D4: 20 | E4: 73
A5: סה"כ חודש" | D5: =SUM(D4:D4) | E5: =SUM(E4:E4)

Sheet יולי 2026
A1: יולי 2026 | July 2026
A2: ← חזרה לסיכום חודשי
A3: תאריך | B3: כלי | C3: תיאור | D3: סכום ($) | E3: סכום (₪)
A4: 2026-07-16 | B4: OpenAI | C4: ChatGPT Plus | D4: 20 | E4: 73
A5: סה"כ חודש" | D5: =SUM(D4:D4) | E5: =SUM(E4:E4)

Sheet אוגוסט 2026
A1: אוגוסט 2026 | August 2026
A2: ← חזרה לסיכום חודשי
A3: תאריך | B3: כלי | C3: תיאור | D3: סכום ($) | E3: סכום (₪)
A4: 2026-08-16 | B4: OpenAI | C4: ChatGPT Plus | D4: 20 | E4: 73
A5: סה"כ חודש" | D5: =SUM(D4:D4) | E5: =SUM(E4:E4)

Sheet ספטמבר 2026
A1: ספטמבר 2026 | September 2026
A2: ← חזרה לסיכום חודשי
A3: תאריך | B3: כלי | C3: תיאור | D3: סכום ($) | E3: סכום (₪)
A4: 2026-09-16 | B4: OpenAI | C4: ChatGPT Plus | D4: 20 | E4: 73
A5: סה"כ חודש" | D5: =SUM(D4:D4) | E5: =SUM(E4:E4)

Sheet אוקטובר 2026
A1: אוקטובר 2026 | October 2026
A2: ← חזרה לסיכום חודשי
A3: תאריך | B3: כלי | C3: תיאור | D3: סכום ($) | E3: סכום (₪)
A4: 2026-10-16 | B4: OpenAI | C4: ChatGPT Plus | D4: 20 | E4: 73
A5: סה"כ חודש" | D5: =SUM(D4:D4) | E5: =SUM(E4:E4)

Sheet נובמבר 2026
A1: נובמבר 2026 | November 2026
A2: ← חזרה לסיכום חודשי
A3: תאריך | B3: כלי | C3: תיאור | D3: סכום ($) | E3: סכום (₪)
A4: 2026-11-16 | B4: OpenAI | C4: ChatGPT Plus | D4: 20 | E4: 73
A5: סה"כ חודש" | D5: =SUM(D4:D4) | E5: =SUM(E4:E4)

Sheet דצמבר 2026
A1: דצמבר 2026 | December 2026
A2: ← חזרה לסיכום חודשי
A3: תאריך | B3: כלי | C3: תיאור | D3: סכום ($) | E3: סכום (₪)
A4: 2026-12-16 | B4: OpenAI | C4: ChatGPT Plus | D4: 20 | E4: 73
A5: סה"כ חודש" | D5: =SUM(D4:D4) | E5: =SUM(E4:E4)

Sheet סיכום חודשי
A1: סיכום חודשי לפי כלי | יולי 2025 – דצמבר 2026
A2: לחץ על שם חודש כדי לצפייה בגליון המפורט ↓ | OpenAI / ChatGPT Plus מתווסף אוטומטית ב-16 לכל חודש
A3: כלי | B3: יולי 2025 (July 2025) | D3: אוגוסט 2025 (August 2025) | F3: ספטמבר 2025 (September 2025) | H3: אוקטובר 2025 (October 2025) | J3: נובמבר 2025 (November 2025) | L3: דצמבר 2025 (December 2025) | N3: ינואר 2026 (January 2026) | P3: פברואר 2026 (February 2026) | R3: מרץ 2026 (March 2026) | T3: אפריל 2026 (April 2026) | V3: מאי 2026 (May 2026) | X3: יוני 2026 (June 2026) | Z3: יולי 2026 (July 2026) | AB3: אוגוסט 2026 (August 2026) | AD3: ספטמבר 2026 (September 2026) | AF3: אוקטובר 2026 (October 2026) | AH3: נובמבר 2026 (November 2026) | AJ3: דצמבר 2026 (December 2026) | AL3: סה"כ ($) | AM3: סה"כ (₪)
B4: $ | C4: ₪ | D4: $ | E4: ₪ | F4: $ | G4: ₪ | H4: $ | I4: ₪ | J4: $ | K4: ₪ | L4: $ | M4: ₪ | N4: $ | O4: ₪ | P4: $ | Q4: ₪ | R4: $ | S4: ₪ | T4: $ | U4: ₪ | V4: $ | W4: ₪ | X4: $ | Y4: ₪ | Z4: $ | AA4: ₪ | AB4: $ | AC4: ₪ | AD4: $ | AE4: ₪ | AF4: $ | AG4: ₪ | AH4: $ | AI4: ₪ | AJ4: $ | AK4: ₪ | AL4: $ | AM4: ₪
A5: Anthropic | B5: =SUMIFS('כל ההוצאות'!$D:$D,'כל ההוצאות'!$B:$B,"Anthropic",'כל ההוצאות'!$F:$F,"יולי 2025") | C5: =SUMIFS('כל ההוצאות'!$E:$E,'כל ההוצאות'!$B:$B,"Anthropic",'כל ההוצאות'!$F:$F,"יולי 2025") | D5: =SUMIFS('כל ההוצאות'!$D:$D,'כל ההוצאות'!$B:$B,"Anthropic",'כל ההוצאות'!$F:$F,"אוגוסט 2025") | E5: =SUMIFS('כל ההוצאות'!$E:$E,'כל ההוצאות'!$B:$B,"Anthropic",'כל ההוצאות'!$F:$F,"אוגוסט 2025") | F5: =SUMIFS('כל ההוצאות'!$D:$D,'כל ההוצאות'!$B:$B,"Anthropic",'כל ההוצאות'!$F:$F,"ספטמבר 2025") | G5: =SUMIFS('כל ההוצאות'!$E:$E,'כל ההוצאות'!$B:$B,"Anthropic",'כל ההוצאות'!$F:$F,"ספטמבר 2025") | H5: =SUMIFS('כל ההוצאות'!$D:$D,'כל ההוצאות'!$B:$B,"Anthropic",'כל ההוצאות'!$F:$F,"אוקטובר 2025") | I5: =SUMIFS('כל ההוצאות'!$E:$E,'כל ההוצאות'!$B:$B,"Anthropic",'כל ההוצאות'!$F:$F,"אוקטובר 2025") | J5: =SUMIFS('כל ההוצאות'!$D:$D,'כל ההוצאות'!$B:$B,"Anthropic",'כל ההוצאות'!$F:$F,"נובמבר 2025") | K5: =SUMIFS('כל ההוצאות'!$E:$E,'כל ההוצאות'!$B:$B,"Anthropic",'כל ההוצאות'!$F:$F,"נובמבר 2025") | L5: =SUMIFS('כל ההוצאות'!$D:$D,'כל ההוצאות'!$B:$B,"Anthropic",'כל ההוצאות'!$F:$F,"דצמבר 2025") | M5: =SUMIFS('כל ההוצאות'!$E:$E,'כל ההוצאות'!$B:$B,"Anthropic",'כל ההוצאות'!$F:$F,"דצמבר 2025") | N5: =SUMIFS('כל ההוצאות'!$D:$D,'כל ההוצאות'!$B:$B,"Anthropic",'כל ההוצאות'!$F:$F,"ינואר 2026") | O5: =SUMIFS('כל ההוצאות'!$E:$E,'כל ההוצאות'!$B:$B,"Anthropic",'כל ההוצאות'!$F:$F,"ינואר 2026") | P5: =SUMIFS('כל ההוצאות'!$D:$D,'כל ההוצאות'!$B:$B,"Anthropic",'כל ההוצאות'!$F:$F,"פברואר 2026") | Q5: =SUMIFS('כל ההוצאות'!$E:$E,'כל ההוצאות'!$B:$B,"Anthropic",'כל ההוצאות'!$F:$F,"פברואר 2026") | R5: =SUMIFS('כל ההוצאות'!$D:$D,'כל ההוצאות'!$B:$B,"Anthropic",'כל ההוצאות'!$F:$F,"מרץ 2026") | S5: =SUMIFS('כל ההוצאות'!$E:$E,'כל ההוצאות'!$B:$B,"Anthropic",'כל ההוצאות'!$F:$F,"מרץ 2026") | T5: =SUMIFS('כל ההוצאות'!$D:$D,'כל ההוצאות'!$B:$B,"Anthropic",'כל ההוצאות'!$F:$F,"אפריל 2026") | U5: =SUMIFS('כל ההוצאות'!$E:$E,'כל ההוצאות'!$B:$B,"Anthropic",'כל ההוצאות'!$F:$F,"אפריל 2026") | V5: =SUMIFS('כל ההוצאות'!$D:$D,'כל ההוצאות'!$B:$B,"Anthropic",'כל ההוצאות'!$F:$F,"מאי 2026") | W5: =SUMIFS('כל ההוצאות'!$E:$E,'כל ההוצאות'!$B:$B,"Anthropic",'כל ההוצאות'!$F:$F,"מאי 2026") | X5: =SUMIFS('כל ההוצאות'!$D:$D,'כל ההוצאות'!$B:$B,"Anthropic",'כל ההוצאות'!$F:$F,"יוני 2026") | Y5: =SUMIFS('כל ההוצאות'!$E:$E,'כל ההוצאות'!$B:$B,"Anthropic",'כל ההוצאות'!$F:$F,"יוני 2026") | Z5: =SUMIFS('כל ההוצאות'!$D:$D,'כל ההוצאות'!$B:$B,"Anthropic",'כל ההוצאות'!$F:$F,"יולי 2026") | AA5: =SUMIFS('כל ההוצאות'!$E:$E,'כל ההוצאות'!$B:$B,"Anthropic",'כל ההוצאות'!$F:$F,"יולי 2026") | AB5: =SUMIFS('כל ההוצאות'!$D:$D,'כל ההוצאות'!$B:$B,"Anthropic",'כל ההוצאות'!$F:$F,"אוגוסט 2026") | AC5: =SUMIFS('כל ההוצאות'!$E:$E,'כל ההוצאות'!$B:$B,"Anthropic",'כל ההוצאות'!$F:$F,"אוגוסט 2026") | AD5: =SUMIFS('כל ההוצאות'!$D:$D,'כל ההוצאות'!$B:$B,"Anthropic",'כל ההוצאות'!$F:$F,"ספטמבר 2026") | AE5: =SUMIFS('כל ההוצאות'!$E:$E,'כל ההוצאות'!$B:$B,"Anthropic",'כל ההוצאות'!$F:$F,"ספטמבר 2026") | AF5: =SUMIFS('כל ההוצאות'!$D:$D,'כל ההוצאות'!$B:$B,"Anthropic",'כל ההוצאות'!$F:$F,"אוקטובר 2026") | AG5: =SUMIFS('כל ההוצאות'!$E:$E,'כל ההוצאות'!$B:$B,"Anthropic",'כל ההוצאות'!$F:$F,"אוקטובר 2026") | AH5: =SUMIFS('כל ההוצאות'!$D:$D,'כל ההוצאות'!$B:$B,"Anthropic",'כל ההוצאות'!$F:$F,"נובמבר 2026") | AI5: =SUMIFS('כל ההוצאות'!$E:$E,'כל ההוצאות'!$B:$B,"Anthropic",'כל ההוצאות'!$F:$F,"נובמבר 2026") | AJ5: =SUMIFS('כל ההוצאות'!$D:$D,'כל ההוצאות'!$B:$B,"Anthropic",'כל ההוצאות'!$F:$F,"דצמבר 2026") | AK5: =SUMIFS('כל ההוצאות'!$E:$E,'כל ההוצאות'!$B:$B,"Anthropic",'כל ההוצאות'!$F:$F,"דצמבר 2026") | AL5: =SUM(B5,D5,F5,H5,J5,L5,N5,P5,R5,T5,V5,X5,Z5,AB5,AD5,AF5,AH5,AJ5) | AM5: =SUM(C5,E5,G5,I5,K5,M5,O5,Q5,S5,U5,W5,Y5,AA5,AC5,AE5,AG5,AI5,AK5)
A6: Astria | B6: =SUMIFS('כל ההוצאות'!$D:$D,'כל ההוצאות'!$B:$B,"Astria",'כל ההוצאות'!$F:$F,"יולי 2025") | C6: =SUMIFS('כל ההוצאות'!$E:$E,'כל ההוצאות'!$B:$B,"Astria",'כל ההוצאות'!$F:$F,"יולי 2025") | D6: =SUMIFS('כל ההוצאות'!$D:$D,'כל ההוצאות'!$B:$B,"Astria",'כל ההוצאות'!$F:$F,"אוגוסט 2025") | E6: =SUMIFS('כל ההוצאות'!$E:$E,'כל ההוצאות'!$B:$B,"Astria",'כל ההוצאות'!$F:$F,"אוגוסט 2025") | F6: =SUMIFS('כל ההוצאות'!$D:$D,'כל ההוצאות'!$B:$B,"Astria",'כל ההוצאות'!$F:$F,"ספטמבר 2025") | G6: =SUMIFS('כל ההוצאות'!$E:$E,'כל ההוצאות'!$B:$B,"Astria",'כל ההוצאות'!$F:$F,"ספטמבר 2025") | H6: =SUMIFS('כל ההוצאות'!$D:$D,'כל ההוצאות'!$B:$B,"Astria",'כל ההוצאות'!$F:$F,"אוקטובר 2025") | I6: =SUMIFS('כל ההוצאות'!$E:$E,'כל ההוצאות'!$B:$B,"Astria",'כל ההוצאות'!$F:$F,"אוקטובר 2025") | J6: =SUMIFS('כל ההוצאות'!$D:$D,'כל ההוצאות'!$B:$B,"Astria",'כל ההוצאות'!$F:$F,"נובמבר 2025") | K6: =SUMIFS('כל ההוצאות'!$E:$E,'כל ההוצאות'!$B:$B,"Astria",'כל ההוצאות'!$F:$F,"נובמבר 2025") | L6: =SUMIFS('כל ההוצאות'!$D:$D,'כל ההוצאות'!$B:$B,"Astria",'כל ההוצאות'!$F:$F,"דצמבר 2025") | M6: =SUMIFS('כל ההוצאות'!$E:$E,'כל ההוצאות'!$B:$B,"Astria",'כל ההוצאות'!$F:$F,"דצמבר 2025") | N6: =SUMIFS('כל ההוצאות'!$D:$D,'כל ההוצאות'!$B:$B,"Astria",'כל ההוצאות'!$F:$F,"ינואר 2026") | O6: =SUMIFS('כל ההוצאות'!$E:$E,'כל ההוצאות'!$B:$B,"Astria",'כל ההוצאות'!$F:$F,"ינואר 2026") | P6: =SUMIFS('כל ההוצאות'!$D:$D,'כל ההוצאות'!$B:$B,"Astria",'כל ההוצאות'!$F:$F,"פברואר 2026") | Q6: =SUMIFS('כל ההוצאות'!$E:$E,'כל ההוצאות'!$B:$B,"Astria",'כל ההוצאות'!$F:$F,"פברואר 2026") | R6: =SUMIFS('כל ההוצאות'!$D:$D,'כל ההוצאות'!$B:$B,"Astria",'כל ההוצאות'!$F:$F,"מרץ 2026") | S6: =SUMIFS('כל ההוצאות'!$E:$E,'כל ההוצאות'!$B:$B,"Astria",'כל ההוצאות'!$F:$F,"מרץ 2026") | T6: =SUMIFS('כל ההוצאות'!$D:$D,'כל ההוצאות'!$B:$B,"Astria",'כל ההוצאות'!$F:$F,"אפריל 2026") | U6: =SUMIFS('כל ההוצאות'!$E:$E,'כל ההוצאות'!$B:$B,"Astria",'כל ההוצאות'!$F:$F,"אפריל 2026") | V6: =SUMIFS('כל ההוצאות'!$D:$D,'כל ההוצאות'!$B:$B,"Astria",'כל ההוצאות'!$F:$F,"מאי 2026") | W6: =SUMIFS('כל ההוצאות'!$E:$E,'כל ההוצאות'!$B:$B,"Astria",'כל ההוצאות'!$F:$F,"מאי 2026") | X6: =SUMIFS('כל ההוצאות'!$D:$D,'כל ההוצאות'!$B:$B,"Astria",'כל ההוצאות'!$F:$F,"יוני 2026") | Y6: =SUMIFS('כל ההוצאות'!$E:$E,'כל ההוצאות'!$B:$B,"Astria",'כל ההוצאות'!$F:$F,"יוני 2026") | Z6: =SUMIFS('כל ההוצאות'!$D:$D,'כל ההוצאות'!$B:$B,"Astria",'כל ההוצאות'!$F:$F,"יולי 2026") | AA6: =SUMIFS('כל ההוצאות'!$E:$E,'כל ההוצאות'!$B:$B,"Astria",'כל ההוצאות'!$F:$F,"יולי 2026") | AB6: =SUMIFS('כל ההוצאות'!$D:$D,'כל ההוצאות'!$B:$B,"Astria",'כל ההוצאות'!$F:$F,"אוגוסט 2026") | AC6: =SUMIFS('כל ההוצאות'!$E:$E,'כל ההוצאות'!$B:$B,"Astria",'כל ההוצאות'!$F:$F,"אוגוסט 2026") | AD6: =SUMIFS('כל ההוצאות'!$D:$D,'כל ההוצאות'!$B:$B,"Astria",'כל ההוצאות'!$F:$F,"ספטמבר 2026") | AE6: =SUMIFS('כל ההוצאות'!$E:$E,'כל ההוצאות'!$B:$B,"Astria",'כל ההוצאות'!$F:$F,"ספטמבר 2026") | AF6: =SUMIFS('כל ההוצאות'!$D:$D,'כל ההוצאות'!$B:$B,"Astria",'כל ההוצאות'!$F:$F,"אוקטובר 2026") | AG6: =SUMIFS('כל ההוצאות'!$E:$E,'כל ההוצאות'!$B:$B,"Astria",'כל ההוצאות'!$F:$F,"אוקטובר 2026") | AH6: =SUMIFS('כל ההוצאות'!$D:$D,'כל ההוצאות'!$B:$B,"Astria",'כל ההוצאות'!$F:$F,"נובמבר 2026") | AI6: =SUMIFS('כל ההוצאות'!$E:$E,'כל ההוצאות'!$B:$B,"Astria",'כל ההוצאות'!$F:$F,"נובמבר 2026") | AJ6: =SUMIFS('כל ההוצאות'!$D:$D,'כל ההוצאות'!$B:$B,"Astria",'כל ההוצאות'!$F:$F,"דצמבר 2026") | AK6: =SUMIFS('כל ההוצאות'!$E:$E,'כל ההוצאות'!$B:$B,"Astria",'כל ההוצאות'!$F:$F,"דצמבר 2026") | AL6: =SUM(B6,D6,F6,H6,J6,L6,N6,P6,R6,T6,V6,X6,Z6,AB6,AD6,AF6,AH6,AJ6) | AM6: =SUM(C6,E6,G6,I6,K6,M6,O6,Q6,S6,U6,W6,Y6,AA6,AC6,AE6,AG6,AI6,AK6)
A7: CapCut | B7: =SUMIFS('כל ההוצאות'!$D:$D,'כל ההוצאות'!$B:$B,"CapCut",'כל ההוצאות'!$F:$F,"יולי 2025") | C7: =SUMIFS('כל ההוצאות'!$E:$E,'כל ההוצאות'!$B:$B,"CapCut",'כל ההוצאות'!$F:$F,"יולי 2025") | D7: =SUMIFS('כל ההוצאות'!$D:$D,'כל ההוצאות'!$B:$B,"CapCut",'כל ההוצאות'!$F:$F,"אוגוסט 2025") | E7: =SUMIFS('כל ההוצאות'!$E:$E,'כל ההוצאות'!$B:$B,"CapCut",'כל ההוצאות'!$F:$F,"אוגוסט 2025") | F7: =SUMIFS('כל ההוצאות'!$D:$D,'כל ההוצאות'!$B:$B,"CapCut",'כל ההוצאות'!$F:$F,"ספטמבר 2025") | G7: =SUMIFS('כל ההוצאות'!$E:$E,'כל ההוצאות'!$B:$B,"CapCut",'כל ההוצאות'!$F:$F,"ספטמבר 2025") | H7: =SUMIFS('כל ההוצאות'!$D:$D,'כל ההוצאות'!$B:$B,"CapCut",'כל ההוצאות'!$F:$F,"אוקטובר 2025") | I7: =SUMIFS('כל ההוצאות'!$E:$E,'כל ההוצאות'!$B:$B,"CapCut",'כל ההוצאות'!$F:$F,"אוקטובר 2025") | J7: =SUMIFS('כל ההוצאות'!$D:$D,'כל ההוצאות'!$B:$B,"CapCut",'כל ההוצאות'!$F:$F,"נובמבר 2025") | K7: =SUMIFS('כל ההוצאות'!$E:$E,'כל ההוצאות'!$B:$B,"CapCut",'כל ההוצאות'!$F:$F,"נובמבר 2025") | L7: =SUMIFS('כל ההוצאות'!$D:$D,'כל ההוצאות'!$B:$B,"CapCut",'כל ההוצאות'!$F:$F,"דצמבר 2025") | M7: =SUMIFS('כל ההוצאות'!$E:$E,'כל ההוצאות'!$B:$B,"CapCut",'כל ההוצאות'!$F:$F,"דצמבר 2025") | N7: =SUMIFS('כל ההוצאות'!$D:$D,'כל ההוצאות'!$B:$B,"CapCut",'כל ההוצאות'!$F:$F,"ינואר 2026") | O7: =SUMIFS('כל ההוצאות'!$E:$E,'כל ההוצאות'!$B:$B,"CapCut",'כל ההוצאות'!$F:$F,"ינואר 2026") | P7: =SUMIFS('כל ההוצאות'!$D:$D,'כל ההוצאות'!$B:$B,"CapCut",'כל ההוצאות'!$F:$F,"פברואר 2026") | Q7: =SUMIFS('כל ההוצאות'!$E:$E,'כל ההוצאות'!$B:$B,"CapCut",'כל ההוצאות'!$F:$F,"פברואר 2026") | R7: =SUMIFS('כל ההוצאות'!$D:$D,'כל ההוצאות'!$B:$B,"CapCut",'כל ההוצאות'!$F:$F,"מרץ 2026") | S7: =SUMIFS('כל ההוצאות'!$E:$E,'כל ההוצאות'!$B:$B,"CapCut",'כל ההוצאות'!$F:$F,"מרץ 2026") | T7: =SUMIFS('כל ההוצאות'!$D:$D,'כל ההוצאות'!$B:$B,"CapCut",'כל ההוצאות'!$F:$F,"אפריל 2026") | U7: =SUMIFS('כל ההוצאות'!$E:$E,'כל ההוצאות'!$B:$B,"CapCut",'כל ההוצאות'!$F:$F,"אפריל 2026") | V7: =SUMIFS('כל ההוצאות'!$D:$D,'כל ההוצאות'!$B:$B,"CapCut",'כל ההוצאות'!$F:$F,"מאי 2026") | W7: =SUMIFS('כל ההוצאות'!$E:$E,'כל ההוצאות'!$B:$B,"CapCut",'כל ההוצאות'!$F:$F,"מאי 2026") | X7: =SUMIFS('כל ההוצאות'!$D:$D,'כל ההוצאות'!$B:$B,"CapCut",'כל ההוצאות'!$F:$F,"יוני 2026") | Y7: =SUMIFS('כל ההוצאות'!$E:$E,'כל ההוצאות'!$B:$B,"CapCut",'כל ההוצאות'!$F:$F,"יוני 2026") | Z7: =SUMIFS('כל ההוצאות'!$D:$D,'כל ההוצאות'!$B:$B,"CapCut",'כל ההוצאות'!$F:$F,"יולי 2026") | AA7: =SUMIFS('כל ההוצאות'!$E:$E,'כל ההוצאות'!$B:$B,"CapCut",'כל ההוצאות'!$F:$F,"יולי 2026") | AB7: =SUMIFS('כל ההוצאות'!$D:$D,'כל ההוצאות'!$B:$B,"CapCut",'כל ההוצאות'!$F:$F,"אוגוסט 2026") | AC7: =SUMIFS('כל ההוצאות'!$E:$E,'כל ההוצאות'!$B:$B,"CapCut",'כל ההוצאות'!$F:$F,"אוגוסט 2026") | AD7: =SUMIFS('כל ההוצאות'!$D:$D,'כל ההוצאות'!$B:$B,"CapCut",'כל ההוצאות'!$F:$F,"ספטמבר 2026") | AE7: =SUMIFS('כל ההוצאות'!$E:$E,'כל ההוצאות'!$B:$B,"CapCut",'כל ההוצאות'!$F:$F,"ספטמבר 2026") | AF7: =SUMIFS('כל ההוצאות'!$D:$D,'כל ההוצאות'!$B:$B,"CapCut",'כל ההוצאות'!$F:$F,"אוקטובר 2026") | AG7: =SUMIFS('כל ההוצאות'!$E:$E,'כל ההוצאות'!$B:$B,"CapCut",'כל ההוצאות'!$F:$F,"אוקטובר 2026") | AH7: =SUMIFS('כל ההוצאות'!$D:$D,'כל ההוצאות'!$B:$B,"CapCut",'כל ההוצאות'!$F:$F,"נובמבר 2026") | AI7: =SUMIFS('כל ההוצאות'!$E:$E,'כל ההוצאות'!$B:$B,"CapCut",'כל ההוצאות'!$F:$F,"נובמבר 2026") | AJ7: =SUMIFS('כל ההוצאות'!$D:$D,'כל ההוצאות'!$B:$B,"CapCut",'כל ההוצאות'!$F:$F,"דצמבר 2026") | AK7: =SUMIFS('כל ההוצאות'!$E:$E,'כל ההוצאות'!$B:$B,"CapCut",'כל ההוצאות'!$F:$F,"דצמבר 2026") | AL7: =SUM(B7,D7,F7,H7,J7,L7,N7,P7,R7,T7,V7,X7,Z7,AB7,AD7,AF7,AH7,AJ7) | AM7: =SUM(C7,E7,G7,I7,K7,M7,O7,Q7,S7,U7,W7,Y7,AA7,AC7,AE7,AG7,AI7,AK7)
A8: Dzine | B8: =SUMIFS('כל ההוצאות'!$D:$D,'כל ההוצאות'!$B:$B,"Dzine",'כל ההוצאות'!$F:$F,"יולי 2025") | C8: =SUMIFS('כל ההוצאות'!$E:$E,'כל ההוצאות'!$B:$B,"Dzine",'כל ההוצאות'!$F:$F,"יולי 2025") | D8: =SUMIFS('כל ההוצאות'!$D:$D,'כל ההוצאות'!$B:$B,"Dzine",'כל ההוצאות'!$F:$F,"אוגוסט 2025") | E8: =SUMIFS('כל ההוצאות'!$E:$E,'כל ההוצאות'!$B:$B,"Dzine",'כל ההוצאות'!$F:$F,"אוגוסט 2025") | F8: =SUMIFS('כל ההוצאות'!$D:$D,'כל ההוצאות'!$B:$B,"Dzine",'כל ההוצאות'!$F:$F,"ספטמבר 2025") | G8: =SUMIFS('כל ההוצאות'!$E:$E,'כל ההוצאות'!$B:$B,"Dzine",'כל ההוצאות'!$F:$F,"ספטמבר 2025") | H8: =SUMIFS('כל ההוצאות'!$D:$D,'כל ההוצאות'!$B:$B,"Dzine",'כל ההוצאות'!$F:$F,"אוקטובר 2025") | I8: =SUMIFS('כל ההוצאות'!$E:$E,'כל ההוצאות'!$B:$B,"Dzine",'כל ההוצאות'!$F:$F,"אוקטובר 2025") | J8: =SUMIFS('כל ההוצאות'!$D:$D,'כל ההוצאות'!$B:$B,"Dzine",'כל ההוצאות'!$F:$F,"נובמבר 2025") | K8: =SUMIFS('כל ההוצאות'!$E:$E,'כל ההוצאות'!$B:$B,"Dzine",'כל ההוצאות'!$F:$F,"נובמבר 2025") | L8: =SUMIFS('כל ההוצאות'!$D:$D,'כל ההוצאות'!$B:$B,"Dzine",'כל ההוצאות'!$F:$F,"דצמבר 2025") | M8: =SUMIFS('כל ההוצאות'!$E:$E,'כל ההוצאות'!$B:$B,"Dzine",'כל ההוצאות'!$F:$F,"דצמבר 2025") | N8: =SUMIFS('כל ההוצאות'!$D:$D,'כל ההוצאות'!$B:$B,"Dzine",'כל ההוצאות'!$F:$F,"ינואר 2026") | O8: =SUMIFS('כל ההוצאות'!$E:$E,'כל ההוצאות'!$B:$B,"Dzine",'כל ההוצאות'!$F:$F,"ינואר 2026") | P8: =SUMIFS('כל ההוצאות'!$D:$D,'כל ההוצאות'!$B:$B,"Dzine",'כל ההוצאות'!$F:$F,"פברואר 2026") | Q8: =SUMIFS('כל ההוצאות'!$E:$E,'כל ההוצאות'!$B:$B,"Dzine",'כל ההוצאות'!$F:$F,"פברואר 2026") | R8: =SUMIFS('כל ההוצאות'!$D:$D,'כל ההוצאות'!$B:$B,"Dzine",'כל ההוצאות'!$F:$F,"מרץ 2026") | S8: =SUMIFS('כל ההוצאות'!$E:$E,'כל ההוצאות'!$B:$B,"Dzine",'כל ההוצאות'!$F:$F,"מרץ 2026") | T8: =SUMIFS('כל ההוצאות'!$D:$D,'כל ההוצאות'!$B:$B,"Dzine",'כל ההוצאות'!$F:$F,"אפריל 2026") | U8: =SUMIFS('כל ההוצאות'!$E:$E,'כל ההוצאות'!$B:$B,"Dzine",'כל ההוצאות'!$F:$F,"אפריל 2026") | V8: =SUMIFS('כל ההוצאות'!$D:$D,'כל ההוצאות'!$B:$B,"Dzine",'כל ההוצאות'!$F:$F,"מאי 2026") | W8: =SUMIFS('כל ההוצאות'!$E:$E,'כל ההוצאות'!$B:$B,"Dzine",'כל ההוצאות'!$F:$F,"מאי 2026") | X8: =SUMIFS('כל ההוצאות'!$D:$D,'כל ההוצאות'!$B:$B,"Dzine",'כל ההוצאות'!$F:$F,"יוני 2026") | Y8: =SUMIFS('כל ההוצאות'!$E:$E,'כל ההוצאות'!$B:$B,"Dzine",'כל ההוצאות'!$F:$F,"יוני 2026") | Z8: =SUMIFS('כל ההוצאות'!$D:$D,'כל ההוצאות'!$B:$B,"Dzine",'כל ההוצאות'!$F:$F,"יולי 2026") | AA8: =SUMIFS('כל ההוצאות'!$E:$E,'כל ההוצאות'!$B:$B,"Dzine",'כל ההוצאות'!$F:$F,"יולי 2026") | AB8: =SUMIFS('כל ההוצאות'!$D:$D,'כל ההוצאות'!$B:$B,"Dzine",'כל ההוצאות'!$F:$F,"אוגוסט 2026") | AC8: =SUMIFS('כל ההוצאות'!$E:$E,'כל ההוצאות'!$B:$B,"Dzine",'כל ההוצאות'!$F:$F,"אוגוסט 2026") | AD8: =SUMIFS('כל ההוצאות'!$D:$D,'כל ההוצאות'!$B:$B,"Dzine",'כל ההוצאות'!$F:$F,"ספטמבר 2026") | AE8: =SUMIFS('כל ההוצאות'!$E:$E,'כל ההוצאות'!$B:$B,"Dzine",'כל ההוצאות'!$F:$F,"ספטמבר 2026") | AF8: =SUMIFS('כל ההוצאות'!$D:$D,'כל ההוצאות'!$B:$B,"Dzine",'כל ההוצאות'!$F:$F,"אוקטובר 2026") | AG8: =SUMIFS('כל ההוצאות'!$E:$E,'כל ההוצאות'!$B:$B,"Dzine",'כל ההוצאות'!$F:$F,"אוקטובר 2026") | AH8: =SUMIFS('כל ההוצאות'!$D:$D,'כל ההוצאות'!$B:$B,"Dzine",'כל ההוצאות'!$F:$F,"נובמבר 2026") | AI8: =SUMIFS('כל ההוצאות'!$E:$E,'כל ההוצאות'!$B:$B,"Dzine",'כל ההוצאות'!$F:$F,"נובמבר 2026") | AJ8: =SUMIFS('כל ההוצאות'!$D:$D,'כל ההוצאות'!$B:$B,"Dzine",'כל ההוצאות'!$F:$F,"דצמבר 2026") | AK8: =SUMIFS('כל ההוצאות'!$E:$E,'כל ההוצאות'!$B:$B,"Dzine",'כל ההוצאות'!$F:$F,"דצמבר 2026") | AL8: =SUM(B8,D8,F8,H8,J8,L8,N8,P8,R8,T8,V8,X8,Z8,AB8,AD8,AF8,AH8,AJ8) | AM8: =SUM(C8,E8,G8,I8,K8,M8,O8,Q8,S8,U8,W8,Y8,AA8,AC8,AE8,AG8,AI8,AK8)
A9: Eleven Labs | B9: =SUMIFS('כל ההוצאות'!$D:$D,'כל ההוצאות'!$B:$B,"Eleven Labs",'כל ההוצאות'!$F:$F,"יולי 2025") | C9: =SUMIFS('כל ההוצאות'!$E:$E,'כל ההוצאות'!$B:$B,"Eleven Labs",'כל ההוצאות'!$F:$F,"יולי 2025") | D9: =SUMIFS('כל ההוצאות'!$D:$D,'כל ההוצאות'!$B:$B,"Eleven Labs",'כל ההוצאות'!$F:$F,"אוגוסט 2025") | E9: =SUMIFS('כל ההוצאות'!$E:$E,'כל ההוצאות'!$B:$B,"Eleven Labs",'כל ההוצאות'!$F:$F,"אוגוסט 2025") | F9: =SUMIFS('כל ההוצאות'!$D:$D,'כל ההוצאות'!$B:$B,"Eleven Labs",'כל ההוצאות'!$F:$F,"ספטמבר 2025") | G9: =SUMIFS('כל ההוצאות'!$E:$E,'כל ההוצאות'!$B:$B,"Eleven Labs",'כל ההוצאות'!$F:$F,"ספטמבר 2025") | H9: =SUMIFS('כל ההוצאות'!$D:$D,'כל ההוצאות'!$B:$B,"Eleven Labs",'כל ההוצאות'!$F:$F,"אוקטובר 2025") | I9: =SUMIFS('כל ההוצאות'!$E:$E,'כל ההוצאות'!$B:$B,"Eleven Labs",'כל ההוצאות'!$F:$F,"אוקטובר 2025") | J9: =SUMIFS('כל ההוצאות'!$D:$D,'כל ההוצאות'!$B:$B,"Eleven Labs",'כל ההוצאות'!$F:$F,"נובמבר 2025") | K9: =SUMIFS('כל ההוצאות'!$E:$E,'כל ההוצאות'!$B:$B,"Eleven Labs",'כל ההוצאות'!$F:$F,"נובמבר 2025") | L9: =SUMIFS('כל ההוצאות'!$D:$D,'כל ההוצאות'!$B:$B,"Eleven Labs",'כל ההוצאות'!$F:$F,"דצמבר 2025") | M9: =SUMIFS('כל ההוצאות'!$E:$E,'כל ההוצאות'!$B:$B,"Eleven Labs",'כל ההוצאות'!$F:$F,"דצמבר 2025") | N9: =SUMIFS('כל ההוצאות'!$D:$D,'כל ההוצאות'!$B:$B,"Eleven Labs",'כל ההוצאות'!$F:$F,"ינואר 2026") | O9: =SUMIFS('כל ההוצאות'!$E:$E,'כל ההוצאות'!$B:$B,"Eleven Labs",'כל ההוצאות'!$F:$F,"ינואר 2026") | P9: =SUMIFS('כל ההוצאות'!$D:$D,'כל ההוצאות'!$B:$B,"Eleven Labs",'כל ההוצאות'!$F:$F,"פברואר 2026") | Q9: =SUMIFS('כל ההוצאות'!$E:$E,'כל ההוצאות'!$B:$B,"Eleven Labs",'כל ההוצאות'!$F:$F,"פברואר 2026") | R9: =SUMIFS('כל ההוצאות'!$D:$D,'כל ההוצאות'!$B:$B,"Eleven Labs",'כל ההוצאות'!$F:$F,"מרץ 2026") | S9: =SUMIFS('כל ההוצאות'!$E:$E,'כל ההוצאות'!$B:$B,"Eleven Labs",'כל ההוצאות'!$F:$F,"מרץ 2026") | T9: =SUMIFS('כל ההוצאות'!$D:$D,'כל ההוצאות'!$B:$B,"Eleven Labs",'כל ההוצאות'!$F:$F,"אפריל 2026") | U9: =SUMIFS('כל ההוצאות'!$E:$E,'כל ההוצאות'!$B:$B,"Eleven Labs",'כל ההוצאות'!$F:$F,"אפריל 2026") | V9: =SUMIFS('כל ההוצאות'!$D:$D,'כל ההוצאות'!$B:$B,"Eleven Labs",'כל ההוצאות'!$F:$F,"מאי 2026") | W9: =SUMIFS('כל ההוצאות'!$E:$E,'כל ההוצאות'!$B:$B,"Eleven Labs",'כל ההוצאות'!$F:$F,"מאי 2026") | X9: =SUMIFS('כל ההוצאות'!$D:$D,'כל ההוצאות'!$B:$B,"Eleven Labs",'כל ההוצאות'!$F:$F,"יוני 2026") | Y9: =SUMIFS('כל ההוצאות'!$E:$E,'כל ההוצאות'!$B:$B,"Eleven Labs",'כל ההוצאות'!$F:$F,"יוני 2026") | Z9: =SUMIFS('כל ההוצאות'!$D:$D,'כל ההוצאות'!$B:$B,"Eleven Labs",'כל ההוצאות'!$F:$F,"יולי 2026") | AA9: =SUMIFS('כל ההוצאות'!$E:$E,'כל ההוצאות'!$B:$B,"Eleven Labs",'כל ההוצאות'!$F:$F,"יולי 2026") | AB9: =SUMIFS('כל ההוצאות'!$D:$D,'כל ההוצאות'!$B:$B,"Eleven Labs",'כל ההוצאות'!$F:$F,"אוגוסט 2026") | AC9: =SUMIFS('כל ההוצאות'!$E:$E,'כל ההוצאות'!$B:$B,"Eleven Labs",'כל ההוצאות'!$F:$F,"אוגוסט 2026") | AD9: =SUMIFS('כל ההוצאות'!$D:$D,'כל ההוצאות'!$B:$B,"Eleven Labs",'כל ההוצאות'!$F:$F,"ספטמבר 2026") | AE9: =SUMIFS('כל ההוצאות'!$E:$E,'כל ההוצאות'!$B:$B,"Eleven Labs",'כל ההוצאות'!$F:$F,"ספטמבר 2026") | AF9: =SUMIFS('כל ההוצאות'!$D:$D,'כל ההוצאות'!$B:$B,"Eleven Labs",'כל ההוצאות'!$F:$F,"אוקטובר 2026") | AG9: =SUMIFS('כל ההוצאות'!$E:$E,'כל ההוצאות'!$B:$B,"Eleven Labs",'כל ההוצאות'!$F:$F,"אוקטובר 2026") | AH9: =SUMIFS('כל ההוצאות'!$D:$D,'כל ההוצאות'!$B:$B,"Eleven Labs",'כל ההוצאות'!$F:$F,"נובמבר 2026") | AI9: =SUMIFS('כל ההוצאות'!$E:$E,'כל ההוצאות'!$B:$B,"Eleven Labs",'כל ההוצאות'!$F:$F,"נובמבר 2026") | AJ9: =SUMIFS('כל ההוצאות'!$D:$D,'כל ההוצאות'!$B:$B,"Eleven Labs",'כל ההוצאות'!$F:$F,"דצמבר 2026") | AK9: =SUMIFS('כל ההוצאות'!$E:$E,'כל ההוצאות'!$B:$B,"Eleven Labs",'כל ההוצאות'!$F:$F,"דצמבר 2026") | AL9: =SUM(B9,D9,F9,H9,J9,L9,N9,P9,R9,T9,V9,X9,Z9,AB9,AD9,AF9,AH9,AJ9) | AM9: =SUM(C9,E9,G9,I9,K9,M9,O9,Q9,S9,U9,W9,Y9,AA9,AC9,AE9,AG9,AI9,AK9)
A10: Genspark | B10: =SUMIFS('כל ההוצאות'!$D:$D,'כל ההוצאות'!$B:$B,"Genspark",'כל ההוצאות'!$F:$F,"יולי 2025") | C10: =SUMIFS('כל ההוצאות'!$E:$E,'כל ההוצאות'!$B:$B,"Genspark",'כל ההוצאות'!$F:$F,"יולי 2025") | D10: =SUMIFS('כל ההוצאות'!$D:$D,'כל ההוצאות'!$B:$B,"Genspark",'כל ההוצאות'!$F:$F,"אוגוסט 2025") | E10: =SUMIFS('כל ההוצאות'!$E:$E,'כל ההוצאות'!$B:$B,"Genspark",'כל ההוצאות'!$F:$F,"אוגוסט 2025") | F10: =SUMIFS('כל ההוצאות'!$D:$D,'כל ההוצאות'!$B:$B,"Genspark",'כל ההוצאות'!$F:$F,"ספטמבר 2025") | G10: =SUMIFS('כל ההוצאות'!$E:$E,'כל ההוצאות'!$B:$B,"Genspark",'כל ההוצאות'!$F:$F,"ספטמבר 2025") | H10: =SUMIFS('כל ההוצאות'!$D:$D,'כל ההוצאות'!$B:$B,"Genspark",'כל ההוצאות'!$F:$F,"אוקטובר 2025") | I10: =SUMIFS('כל ההוצאות'!$E:$E,'כל ההוצאות'!$B:$B,"Genspark",'כל ההוצאות'!$F:$F,"אוקטובר 2025") | J10: =SUMIFS('כל ההוצאות'!$D:$D,'כל ההוצאות'!$B:$B,"Genspark",'כל ההוצאות'!$F:$F,"נובמבר 2025") | K10: =SUMIFS('כל ההוצאות'!$E:$E,'כל ההוצאות'!$B:$B,"Genspark",'כל ההוצאות'!$F:$F,"נובמבר 2025") | L10: =SUMIFS('כל ההוצאות'!$D:$D,'כל ההוצאות'!$B:$B,"Genspark",'כל ההוצאות'!$F:$F,"דצמבר 2025") | M10: =SUMIFS('כל ההוצאות'!$E:$E,'כל ההוצאות'!$B:$B,"Genspark",'כל ההוצאות'!$F:$F,"דצמבר 2025") | N10: =SUMIFS('כל ההוצאות'!$D:$D,'כל ההוצאות'!$B:$B,"Genspark",'כל ההוצאות'!$F:$F,"ינואר 2026") | O10: =SUMIFS('כל ההוצאות'!$E:$E,'כל ההוצאות'!$B:$B,"Genspark",'כל ההוצאות'!$F:$F,"ינואר 2026") | P10: =SUMIFS('כל ההוצאות'!$D:$D,'כל ההוצאות'!$B:$B,"Genspark",'כל ההוצאות'!$F:$F,"פברואר 2026") | Q10: =SUMIFS('כל ההוצאות'!$E:$E,'כל ההוצאות'!$B:$B,"Genspark",'כל ההוצאות'!$F:$F,"פברואר 2026") | R10: =SUMIFS('כל ההוצאות'!$D:$D,'כל ההוצאות'!$B:$B,"Genspark",'כל ההוצאות'!$F:$F,"מרץ 2026") | S10: =SUMIFS('כל ההוצאות'!$E:$E,'כל ההוצאות'!$B:$B,"Genspark",'כל ההוצאות'!$F:$F,"מרץ 2026") | T10: =SUMIFS('כל ההוצאות'!$D:$D,'כל ההוצאות'!$B:$B,"Genspark",'כל ההוצאות'!$F:$F,"אפריל 2026") | U10: =SUMIFS('כל ההוצאות'!$E:$E,'כל ההוצאות'!$B:$B,"Genspark",'כל ההוצאות'!$F:$F,"אפריל 2026") | V10: =SUMIFS('כל ההוצאות'!$D:$D,'כל ההוצאות'!$B:$B,"Genspark",'כל ההוצאות'!$F:$F,"מאי 2026") | W10: =SUMIFS('כל ההוצאות'!$E:$E,'כל ההוצאות'!$B:$B,"Genspark",'כל ההוצאות'!$F:$F,"מאי 2026") | X10: =SUMIFS('כל ההוצאות'!$D:$D,'כל ההוצאות'!$B:$B,"Genspark",'כל ההוצאות'!$F:$F,"יוני 2026") | Y10: =SUMIFS('כל ההוצאות'!$E:$E,'כל ההוצאות'!$B:$B,"Genspark",'כל ההוצאות'!$F:$F,"יוני 2026") | Z10: =SUMIFS('כל ההוצאות'!$D:$D,'כל ההוצאות'!$B:$B,"Genspark",'כל ההוצאות'!$F:$F,"יולי 2026") | AA10: =SUMIFS('כל ההוצאות'!$E:$E,'כל ההוצאות'!$B:$B,"Genspark",'כל ההוצאות'!$F:$F,"יולי 2026") | AB10: =SUMIFS('כל ההוצאות'!$D:$D,'כל ההוצאות'!$B:$B,"Genspark",'כל ההוצאות'!$F:$F,"אוגוסט 2026") | AC10: =SUMIFS('כל ההוצאות'!$E:$E,'כל ההוצאות'!$B:$B,"Genspark",'כל ההוצאות'!$F:$F,"אוגוסט 2026") | AD10: =SUMIFS('כל ההוצאות'!$D:$D,'כל ההוצאות'!$B:$B,"Genspark",'כל ההוצאות'!$F:$F,"ספטמבר 2026") | AE10: =SUMIFS('כל ההוצאות'!$E:$E,'כל ההוצאות'!$B:$B,"Genspark",'כל ההוצאות'!$F:$F,"ספטמבר 2026") | AF10: =SUMIFS('כל ההוצאות'!$D:$D,'כל ההוצאות'!$B:$B,"Genspark",'כל ההוצאות'!$F:$F,"אוקטובר 2026") | AG10: =SUMIFS('כל ההוצאות'!$E:$E,'כל ההוצאות'!$B:$B,"Genspark",'כל ההוצאות'!$F:$F,"אוקטובר 2026") | AH10: =SUMIFS('כל ההוצאות'!$D:$D,'כל ההוצאות'!$B:$B,"Genspark",'כל ההוצאות'!$F:$F,"נובמבר 2026") | AI10: =SUMIFS('כל ההוצאות'!$E:$E,'כל ההוצאות'!$B:$B,"Genspark",'כל ההוצאות'!$F:$F,"נובמבר 2026") | AJ10: =SUMIFS('כל ההוצאות'!$D:$D,'כל ההוצאות'!$B:$B,"Genspark",'כל ההוצאות'!$F:$F,"דצמבר 2026") | AK10: =SUMIFS('כל ההוצאות'!$E:$E,'כל ההוצאות'!$B:$B,"Genspark",'כל ההוצאות'!$F:$F,"דצמבר 2026") | AL10: =SUM(B10,D10,F10,H10,J10,L10,N10,P10,R10,T10,V10,X10,Z10,AB10,AD10,AF10,AH10,AJ10) | AM10: =SUM(C10,E10,G10,I10,K10,M10,O10,Q10,S10,U10,W10,Y10,AA10,AC10,AE10,AG10,AI10,AK10)
A11: Google Cloud | B11: =SUMIFS('כל ההוצאות'!$D:$D,'כל ההוצאות'!$B:$B,"Google Cloud",'כל ההוצאות'!$F:$F,"יולי 2025") | C11: =SUMIFS('כל ההוצאות'!$E:$E,'כל ההוצאות'!$B:$B,"Google Cloud",'כל ההוצאות'!$F:$F,"יולי 2025") | D11: =SUMIFS('כל ההוצאות'!$D:$D,'כל ההוצאות'!$B:$B,"Google Cloud",'כל ההוצאות'!$F:$F,"אוגוסט 2025") | E11: =SUMIFS('כל ההוצאות'!$E:$E,'כל ההוצאות'!$B:$B,"Google Cloud",'כל ההוצאות'!$F:$F,"אוגוסט 2025") | F11: =SUMIFS('כל ההוצאות'!$D:$D,'כל ההוצאות'!$B:$B,"Google Cloud",'כל ההוצאות'!$F:$F,"ספטמבר 2025") | G11: =SUMIFS('כל ההוצאות'!$E:$E,'כל ההוצאות'!$B:$B,"Google Cloud",'כל ההוצאות'!$F:$F,"ספטמבר 2025") | H11: =SUMIFS('כל ההוצאות'!$D:$D,'כל ההוצאות'!$B:$B,"Google Cloud",'כל ההוצאות'!$F:$F,"אוקטובר 2025") | I11: =SUMIFS('כל ההוצאות'!$E:$E,'כל ההוצאות'!$B:$B,"Google Cloud",'כל ההוצאות'!$F:$F,"אוקטובר 2025") | J11: =SUMIFS('כל ההוצאות'!$D:$D,'כל ההוצאות'!$B:$B,"Google Cloud",'כל ההוצאות'!$F:$F,"נובמבר 2025") | K11: =SUMIFS('כל ההוצאות'!$E:$E,'כל ההוצאות'!$B:$B,"Google Cloud",'כל ההוצאות'!$F:$F,"נובמבר 2025") | L11: =SUMIFS('כל ההוצאות'!$D:$D,'כל ההוצאות'!$B:$B,"Google Cloud",'כל ההוצאות'!$F:$F,"דצמבר 2025") | M11: =SUMIFS('כל ההוצאות'!$E:$E,'כל ההוצאות'!$B:$B,"Google Cloud",'כל ההוצאות'!$F:$F,"דצמבר 2025") | N11: =SUMIFS('כל ההוצאות'!$D:$D,'כל ההוצאות'!$B:$B,"Google Cloud",'כל ההוצאות'!$F:$F,"ינואר 2026") | O11: =SUMIFS('כל ההוצאות'!$E:$E,'כל ההוצאות'!$B:$B,"Google Cloud",'כל ההוצאות'!$F:$F,"ינואר 2026") | P11: =SUMIFS('כל ההוצאות'!$D:$D,'כל ההוצאות'!$B:$B,"Google Cloud",'כל ההוצאות'!$F:$F,"פברואר 2026") | Q11: =SUMIFS('כל ההוצאות'!$E:$E,'כל ההוצאות'!$B:$B,"Google Cloud",'כל ההוצאות'!$F:$F,"פברואר 2026") | R11: =SUMIFS('כל ההוצאות'!$D:$D,'כל ההוצאות'!$B:$B,"Google Cloud",'כל ההוצאות'!$F:$F,"מרץ 2026") | S11: =SUMIFS('כל ההוצאות'!$E:$E,'כל ההוצאות'!$B:$B,"Google Cloud",'כל ההוצאות'!$F:$F,"מרץ 2026") | T11: =SUMIFS('כל ההוצאות'!$D:$D,'כל ההוצאות'!$B:$B,"Google Cloud",'כל ההוצאות'!$F:$F,"אפריל 2026") | U11: =SUMIFS('כל ההוצאות'!$E:$E,'כל ההוצאות'!$B:$B,"Google Cloud",'כל ההוצאות'!$F:$F,"אפריל 2026") | V11: =SUMIFS('כל ההוצאות'!$D:$D,'כל ההוצאות'!$B:$B,"Google Cloud",'כל ההוצאות'!$F:$F,"מאי 2026") | W11: =SUMIFS('כל ההוצאות'!$E:$E,'כל ההוצאות'!$B:$B,"Google Cloud",'כל ההוצאות'!$F:$F,"מאי 2026") | X11: =SUMIFS('כל ההוצאות'!$D:$D,'כל ההוצאות'!$B:$B,"Google Cloud",'כל ההוצאות'!$F:$F,"יוני 2026") | Y11: =SUMIFS('כל ההוצאות'!$E:$E,'כל ההוצאות'!$B:$B,"Google Cloud",'כל ההוצאות'!$F:$F,"יוני 2026") | Z11: =SUMIFS('כל ההוצאות'!$D:$D,'כל ההוצאות'!$B:$B,"Google Cloud",'כל ההוצאות'!$F:$F,"יולי 2026") | AA11: =SUMIFS('כל ההוצאות'!$E:$E,'כל ההוצאות'!$B:$B,"Google Cloud",'כל ההוצאות'!$F:$F,"יולי 2026") | AB11: =SUMIFS('כל ההוצאות'!$D:$D,'כל ההוצאות'!$B:$B,"Google Cloud",'כל ההוצאות'!$F:$F,"אוגוסט 2026") | AC11: =SUMIFS('כל ההוצאות'!$E:$E,'כל ההוצאות'!$B:$B,"Google Cloud",'כל ההוצאות'!$F:$F,"אוגוסט 2026") | AD11: =SUMIFS('כל ההוצאות'!$D:$D,'כל ההוצאות'!$B:$B,"Google Cloud",'כל ההוצאות'!$F:$F,"ספטמבר 2026") | AE11: =SUMIFS('כל ההוצאות'!$E:$E,'כל ההוצאות'!$B:$B,"Google Cloud",'כל ההוצאות'!$F:$F,"ספטמבר 2026") | AF11: =SUMIFS('כל ההוצאות'!$D:$D,'כל ההוצאות'!$B:$B,"Google Cloud",'כל ההוצאות'!$F:$F,"אוקטובר 2026") | AG11: =SUMIFS('כל ההוצאות'!$E:$E,'כל ההוצאות'!$B:$B,"Google Cloud",'כל ההוצאות'!$F:$F,"אוקטובר 2026") | AH11: =SUMIFS('כל ההוצאות'!$D:$D,'כל ההוצאות'!$B:$B,"Google Cloud",'כל ההוצאות'!$F:$F,"נובמבר 2026") | AI11: =SUMIFS('כל ההוצאות'!$E:$E,'כל ההוצאות'!$B:$B,"Google Cloud",'כל ההוצאות'!$F:$F,"נובמבר 2026") | AJ11: =SUMIFS('כל ההוצאות'!$D:$D,'כל ההוצאות'!$B:$B,"Google Cloud",'כל ההוצאות'!$F:$F,"דצמבר 2026") | AK11: =SUMIFS('כל ההוצאות'!$E:$E,'כל ההוצאות'!$B:$B,"Google Cloud",'כל ההוצאות'!$F:$F,"דצמבר 2026") | AL11: =SUM(B11,D11,F11,H11,J11,L11,N11,P11,R11,T11,V11,X11,Z11,AB11,AD11,AF11,AH11,AJ11) | AM11: =SUM(C11,E11,G11,I11,K11,M11,O11,Q11,S11,U11,W11,Y11,AA11,AC11,AE11,AG11,AI11,AK11)
A12: Google Workspace | B12: =SUMIFS('כל ההוצאות'!$D:$D,'כל ההוצאות'!$B:$B,"Google Workspace",'כל ההוצאות'!$F:$F,"יולי 2025") | C12: =SUMIFS('כל ההוצאות'!$E:$E,'כל ההוצאות'!$B:$B,"Google Workspace",'כל ההוצאות'!$F:$F,"יולי 2025") | D12: =SUMIFS('כל ההוצאות'!$D:$D,'כל ההוצאות'!$B:$B,"Google Workspace",'כל ההוצאות'!$F:$F,"אוגוסט 2025") | E12: =SUMIFS('כל ההוצאות'!$E:$E,'כל ההוצאות'!$B:$B,"Google Workspace",'כל ההוצאות'!$F:$F,"אוגוסט 2025") | F12: =SUMIFS('כל ההוצאות'!$D:$D,'כל ההוצאות'!$B:$B,"Google Workspace",'כל ההוצאות'!$F:$F,"ספטמבר 2025") | G12: =SUMIFS('כל ההוצאות'!$E:$E,'כל ההוצאות'!$B:$B,"Google Workspace",'כל ההוצאות'!$F:$F,"ספטמבר 2025") | H12: =SUMIFS('כל ההוצאות'!$D:$D,'כל ההוצאות'!$B:$B,"Google Workspace",'כל ההוצאות'!$F:$F,"אוקטובר 2025") | I12: =SUMIFS('כל ההוצאות'!$E:$E,'כל ההוצאות'!$B:$B,"Google Workspace",'כל ההוצאות'!$F:$F,"אוקטובר 2025") | J12: =SUMIFS('כל ההוצאות'!$D:$D,'כל ההוצאות'!$B:$B,"Google Workspace",'כל ההוצאות'!$F:$F,"נובמבר 2025") | K12: =SUMIFS('כל ההוצאות'!$E:$E,'כל ההוצאות'!$B:$B,"Google Workspace",'כל ההוצאות'!$F:$F,"נובמבר 2025") | L12: =SUMIFS('כל ההוצאות'!$D:$D,'כל ההוצאות'!$B:$B,"Google Workspace",'כל ההוצאות'!$F:$F,"דצמבר 2025") | M12: =SUMIFS('כל ההוצאות'!$E:$E,'כל ההוצאות'!$B:$B,"Google Workspace",'כל ההוצאות'!$F:$F,"דצמבר 2025") | N12: =SUMIFS('כל ההוצאות'!$D:$D,'כל ההוצאות'!$B:$B,"Google Workspace",'כל ההוצאות'!$F:$F,"ינואר 2026") | O12: =SUMIFS('כל ההוצאות'!$E:$E,'כל ההוצאות'!$B:$B,"Google Workspace",'כל ההוצאות'!$F:$F,"ינואר 2026") | P12: =SUMIFS('כל ההוצאות'!$D:$D,'כל ההוצאות'!$B:$B,"Google Workspace",'כל ההוצאות'!$F:$F,"פברואר 2026") | Q12: =SUMIFS('כל ההוצאות'!$E:$E,'כל ההוצאות'!$B:$B,"Google Workspace",'כל ההוצאות'!$F:$F,"פברואר 2026") | R12: =SUMIFS('כל ההוצאות'!$D:$D,'כל ההוצאות'!$B:$B,"Google Workspace",'כל ההוצאות'!$F:$F,"מרץ 2026") | S12: =SUMIFS('כל ההוצאות'!$E:$E,'כל ההוצאות'!$B:$B,"Google Workspace",'כל ההוצאות'!$F:$F,"מרץ 2026") | T12: =SUMIFS('כל ההוצאות'!$D:$D,'כל ההוצאות'!$B:$B,"Google Workspace",'כל ההוצאות'!$F:$F,"אפריל 2026") | U12: =SUMIFS('כל ההוצאות'!$E:$E,'כל ההוצאות'!$B:$B,"Google Workspace",'כל ההוצאות'!$F:$F,"אפריל 2026") | V12: =SUMIFS('כל ההוצאות'!$D:$D,'כל ההוצאות'!$B:$B,"Google Workspace",'כל ההוצאות'!$F:$F,"מאי 2026") | W12: =SUMIFS('כל ההוצאות'!$E:$E,'כל ההוצאות'!$B:$B,"Google Workspace",'כל ההוצאות'!$F:$F,"מאי 2026") | X12: =SUMIFS('כל ההוצאות'!$D:$D,'כל ההוצאות'!$B:$B,"Google Workspace",'כל ההוצאות'!$F:$F,"יוני 2026") | Y12: =SUMIFS('כל ההוצאות'!$E:$E,'כל ההוצאות'!$B:$B,"Google Workspace",'כל ההוצאות'!$F:$F,"יוני 2026") | Z12: =SUMIFS('כל ההוצאות'!$D:$D,'כל ההוצאות'!$B:$B,"Google Workspace",'כל ההוצאות'!$F:$F,"יולי 2026") | AA12: =SUMIFS('כל ההוצאות'!$E:$E,'כל ההוצאות'!$B:$B,"Google Workspace",'כל ההוצאות'!$F:$F,"יולי 2026") | AB12: =SUMIFS('כל ההוצאות'!$D:$D,'כל ההוצאות'!$B:$B,"Google Workspace",'כל ההוצאות'!$F:$F,"אוגוסט 2026") | AC12: =SUMIFS('כל ההוצאות'!$E:$E,'כל ההוצאות'!$B:$B,"Google Workspace",'כל ההוצאות'!$F:$F,"אוגוסט 2026") | AD12: =SUMIFS('כל ההוצאות'!$D:$D,'כל ההוצאות'!$B:$B,"Google Workspace",'כל ההוצאות'!$F:$F,"ספטמבר 2026") | AE12: =SUMIFS('כל ההוצאות'!$E:$E,'כל ההוצאות'!$B:$B,"Google Workspace",'כל ההוצאות'!$F:$F,"ספטמבר 2026") | AF12: =SUMIFS('כל ההוצאות'!$D:$D,'כל ההוצאות'!$B:$B,"Google Workspace",'כל ההוצאות'!$F:$F,"אוקטובר 2026") | AG12: =SUMIFS('כל ההוצאות'!$E:$E,'כל ההוצאות'!$B:$B,"Google Workspace",'כל ההוצאות'!$F:$F,"אוקטובר 2026") | AH12: =SUMIFS('כל ההוצאות'!$D:$D,'כל ההוצאות'!$B:$B,"Google Workspace",'כל ההוצאות'!$F:$F,"נובמבר 2026") | AI12: =SUMIFS('כל ההוצאות'!$E:$E,'כל ההוצאות'!$B:$B,"Google Workspace",'כל ההוצאות'!$F:$F,"נובמבר 2026") | AJ12: =SUMIFS('כל ההוצאות'!$D:$D,'כל ההוצאות'!$B:$B,"Google Workspace",'כל ההוצאות'!$F:$F,"דצמבר 2026") | AK12: =SUMIFS('כל ההוצאות'!$E:$E,'כל ההוצאות'!$B:$B,"Google Workspace",'כל ההוצאות'!$F:$F,"דצמבר 2026") | AL12: =SUM(B12,D12,F12,H12,J12,L12,N12,P12,R12,T12,V12,X12,Z12,AB12,AD12,AF12,AH12,AJ12) | AM12: =SUM(C12,E12,G12,I12,K12,M12,O12,Q12,S12,U12,W12,Y12,AA12,AC12,AE12,AG12,AI12,AK12)
A13: Hedra | B13: =SUMIFS('כל ההוצאות'!$D:$D,'כל ההוצאות'!$B:$B,"Hedra",'כל ההוצאות'!$F:$F,"יולי 2025") | C13: =SUMIFS('כל ההוצאות'!$E:$E,'כל ההוצאות'!$B:$B,"Hedra",'כל ההוצאות'!$F:$F,"יולי 2025") | D13: =SUMIFS('כל ההוצאות'!$D:$D,'כל ההוצאות'!$B:$B,"Hedra",'כל ההוצאות'!$F:$F,"אוגוסט 2025") | E13: =SUMIFS('כל ההוצאות'!$E:$E,'כל ההוצאות'!$B:$B,"Hedra",'כל ההוצאות'!$F:$F,"אוגוסט 2025") | F13: =SUMIFS('כל ההוצאות'!$D:$D,'כל ההוצאות'!$B:$B,"Hedra",'כל ההוצאות'!$F:$F,"ספטמבר 2025") | G13: =SUMIFS('כל ההוצאות'!$E:$E,'כל ההוצאות'!$B:$B,"Hedra",'כל ההוצאות'!$F:$F,"ספטמבר 2025") | H13: =SUMIFS('כל ההוצאות'!$D:$D,'כל ההוצאות'!$B:$B,"Hedra",'כל ההוצאות'!$F:$F,"אוקטובר 2025") | I13: =SUMIFS('כל ההוצאות'!$E:$E,'כל ההוצאות'!$B:$B,"Hedra",'כל ההוצאות'!$F:$F,"אוקטובר 2025") | J13: =SUMIFS('כל ההוצאות'!$D:$D,'כל ההוצאות'!$B:$B,"Hedra",'כל ההוצאות'!$F:$F,"נובמבר 2025") | K13: =SUMIFS('כל ההוצאות'!$E:$E,'כל ההוצאות'!$B:$B,"Hedra",'כל ההוצאות'!$F:$F,"נובמבר 2025") | L13: =SUMIFS('כל ההוצאות'!$D:$D,'כל ההוצאות'!$B:$B,"Hedra",'כל ההוצאות'!$F:$F,"דצמבר 2025") | M13: =SUMIFS('כל ההוצאות'!$E:$E,'כל ההוצאות'!$B:$B,"Hedra",'כל ההוצאות'!$F:$F,"דצמבר 2025") | N13: =SUMIFS('כל ההוצאות'!$D:$D,'כל ההוצאות'!$B:$B,"Hedra",'כל ההוצאות'!$F:$F,"ינואר 2026") | O13: =SUMIFS('כל ההוצאות'!$E:$E,'כל ההוצאות'!$B:$B,"Hedra",'כל ההוצאות'!$F:$F,"ינואר 2026") | P13: =SUMIFS('כל ההוצאות'!$D:$D,'כל ההוצאות'!$B:$B,"Hedra",'כל ההוצאות'!$F:$F,"פברואר 2026") | Q13: =SUMIFS('כל ההוצאות'!$E:$E,'כל ההוצאות'!$B:$B,"Hedra",'כל ההוצאות'!$F:$F,"פברואר 2026") | R13: =SUMIFS('כל ההוצאות'!$D:$D,'כל ההוצאות'!$B:$B,"Hedra",'כל ההוצאות'!$F:$F,"מרץ 2026") | S13: =SUMIFS('כל ההוצאות'!$E:$E,'כל ההוצאות'!$B:$B,"Hedra",'כל ההוצאות'!$F:$F,"מרץ 2026") | T13: =SUMIFS('כל ההוצאות'!$D:$D,'כל ההוצאות'!$B:$B,"Hedra",'כל ההוצאות'!$F:$F,"אפריל 2026") | U13: =SUMIFS('כל ההוצאות'!$E:$E,'כל ההוצאות'!$B:$B,"Hedra",'כל ההוצאות'!$F:$F,"אפריל 2026") | V13: =SUMIFS('כל ההוצאות'!$D:$D,'כל ההוצאות'!$B:$B,"Hedra",'כל ההוצאות'!$F:$F,"מאי 2026") | W13: =SUMIFS('כל ההוצאות'!$E:$E,'כל ההוצאות'!$B:$B,"Hedra",'כל ההוצאות'!$F:$F,"מאי 2026") | X13: =SUMIFS('כל ההוצאות'!$D:$D,'כל ההוצאות'!$B:$B,"Hedra",'כל ההוצאות'!$F:$F,"יוני 2026") | Y13: =SUMIFS('כל ההוצאות'!$E:$E,'כל ההוצאות'!$B:$B,"Hedra",'כל ההוצאות'!$F:$F,"יוני 2026") | Z13: =SUMIFS('כל ההוצאות'!$D:$D,'כל ההוצאות'!$B:$B,"Hedra",'כל ההוצאות'!$F:$F,"יולי 2026") | AA13: =SUMIFS('כל ההוצאות'!$E:$E,'כל ההוצאות'!$B:$B,"Hedra",'כל ההוצאות'!$F:$F,"יולי 2026") | AB13: =SUMIFS('כל ההוצאות'!$D:$D,'כל ההוצאות'!$B:$B,"Hedra",'כל ההוצאות'!$F:$F,"אוגוסט 2026") | AC13: =SUMIFS('כל ההוצאות'!$E:$E,'כל ההוצאות'!$B:$B,"Hedra",'כל ההוצאות'!$F:$F,"אוגוסט 2026") | AD13: =SUMIFS('כל ההוצאות'!$D:$D,'כל ההוצאות'!$B:$B,"Hedra",'כל ההוצאות'!$F:$F,"ספטמבר 2026") | AE13: =SUMIFS('כל ההוצאות'!$E:$E,'כל ההוצאות'!$B:$B,"Hedra",'כל ההוצאות'!$F:$F,"ספטמבר 2026") | AF13: =SUMIFS('כל ההוצאות'!$D:$D,'כל ההוצאות'!$B:$B,"Hedra",'כל ההוצאות'!$F:$F,"אוקטובר 2026") | AG13: =SUMIFS('כל ההוצאות'!$E:$E,'כל ההוצאות'!$B:$B,"Hedra",'כל ההוצאות'!$F:$F,"אוקטובר 2026") | AH13: =SUMIFS('כל ההוצאות'!$D:$D,'כל ההוצאות'!$B:$B,"Hedra",'כל ההוצאות'!$F:$F,"נובמבר 2026") | AI13: =SUMIFS('כל ההוצאות'!$E:$E,'כל ההוצאות'!$B:$B,"Hedra",'כל ההוצאות'!$F:$F,"נובמבר 2026") | AJ13: =SUMIFS('כל ההוצאות'!$D:$D,'כל ההוצאות'!$B:$B,"Hedra",'כל ההוצאות'!$F:$F,"דצמבר 2026") | AK13: =SUMIFS('כל ההוצאות'!$E:$E,'כל ההוצאות'!$B:$B,"Hedra",'כל ההוצאות'!$F:$F,"דצמבר 2026") | AL13: =SUM(B13,D13,F13,H13,J13,L13,N13,P13,R13,T13,V13,X13,Z13,AB13,AD13,AF13,AH13,AJ13) | AM13: =SUM(C13,E13,G13,I13,K13,M13,O13,Q13,S13,U13,W13,Y13,AA13,AC13,AE13,AG13,AI13,AK13)
A14: Higgsfield | B14: =SUMIFS('כל ההוצאות'!$D:$D,'כל ההוצאות'!$B:$B,"Higgsfield",'כל ההוצאות'!$F:$F,"יולי 2025") | C14: =SUMIFS('כל ההוצאות'!$E:$E,'כל ההוצאות'!$B:$B,"Higgsfield",'כל ההוצאות'!$F:$F,"יולי 2025") | D14: =SUMIFS('כל ההוצאות'!$D:$D,'כל ההוצאות'!$B:$B,"Higgsfield",'כל ההוצאות'!$F:$F,"אוגוסט 2025") | E14: =SUMIFS('כל ההוצאות'!$E:$E,'כל ההוצאות'!$B:$B,"Higgsfield",'כל ההוצאות'!$F:$F,"אוגוסט 2025") | F14: =SUMIFS('כל ההוצאות'!$D:$D,'כל ההוצאות'!$B:$B,"Higgsfield",'כל ההוצאות'!$F:$F,"ספטמבר 2025") | G14: =SUMIFS('כל ההוצאות'!$E:$E,'כל ההוצאות'!$B:$B,"Higgsfield",'כל ההוצאות'!$F:$F,"ספטמבר 2025") | H14: =SUMIFS('כל ההוצאות'!$D:$D,'כל ההוצאות'!$B:$B,"Higgsfield",'כל ההוצאות'!$F:$F,"אוקטובר 2025") | I14: =SUMIFS('כל ההוצאות'!$E:$E,'כל ההוצאות'!$B:$B,"Higgsfield",'כל ההוצאות'!$F:$F,"אוקטובר 2025") | J14: =SUMIFS('כל ההוצאות'!$D:$D,'כל ההוצאות'!$B:$B,"Higgsfield",'כל ההוצאות'!$F:$F,"נובמבר 2025") | K14: =SUMIFS('כל ההוצאות'!$E:$E,'כל ההוצאות'!$B:$B,"Higgsfield",'כל ההוצאות'!$F:$F,"נובמבר 2025") | L14: =SUMIFS('כל ההוצאות'!$D:$D,'כל ההוצאות'!$B:$B,"Higgsfield",'כל ההוצאות'!$F:$F,"דצמבר 2025") | M14: =SUMIFS('כל ההוצאות'!$E:$E,'כל ההוצאות'!$B:$B,"Higgsfield",'כל ההוצאות'!$F:$F,"דצמבר 2025") | N14: =SUMIFS('כל ההוצאות'!$D:$D,'כל ההוצאות'!$B:$B,"Higgsfield",'כל ההוצאות'!$F:$F,"ינואר 2026") | O14: =SUMIFS('כל ההוצאות'!$E:$E,'כל ההוצאות'!$B:$B,"Higgsfield",'כל ההוצאות'!$F:$F,"ינואר 2026") | P14: =SUMIFS('כל ההוצאות'!$D:$D,'כל ההוצאות'!$B:$B,"Higgsfield",'כל ההוצאות'!$F:$F,"פברואר 2026") | Q14: =SUMIFS('כל ההוצאות'!$E:$E,'כל ההוצאות'!$B:$B,"Higgsfield",'כל ההוצאות'!$F:$F,"פברואר 2026") | R14: =SUMIFS('כל ההוצאות'!$D:$D,'כל ההוצאות'!$B:$B,"Higgsfield",'כל ההוצאות'!$F:$F,"מרץ 2026") | S14: =SUMIFS('כל ההוצאות'!$E:$E,'כל ההוצאות'!$B:$B,"Higgsfield",'כל ההוצאות'!$F:$F,"מרץ 2026") | T14: =SUMIFS('כל ההוצאות'!$D:$D,'כל ההוצאות'!$B:$B,"Higgsfield",'כל ההוצאות'!$F:$F,"אפריל 2026") | U14: =SUMIFS('כל ההוצאות'!$E:$E,'כל ההוצאות'!$B:$B,"Higgsfield",'כל ההוצאות'!$F:$F,"אפריל 2026") | V14: =SUMIFS('כל ההוצאות'!$D:$D,'כל ההוצאות'!$B:$B,"Higgsfield",'כל ההוצאות'!$F:$F,"מאי 2026") | W14: =SUMIFS('כל ההוצאות'!$E:$E,'כל ההוצאות'!$B:$B,"Higgsfield",'כל ההוצאות'!$F:$F,"מאי 2026") | X14: =SUMIFS('כל ההוצאות'!$D:$D,'כל ההוצאות'!$B:$B,"Higgsfield",'כל ההוצאות'!$F:$F,"יוני 2026") | Y14: =SUMIFS('כל ההוצאות'!$E:$E,'כל ההוצאות'!$B:$B,"Higgsfield",'כל ההוצאות'!$F:$F,"יוני 2026") | Z14: =SUMIFS('כל ההוצאות'!$D:$D,'כל ההוצאות'!$B:$B,"Higgsfield",'כל ההוצאות'!$F:$F,"יולי 2026") | AA14: =SUMIFS('כל ההוצאות'!$E:$E,'כל ההוצאות'!$B:$B,"Higgsfield",'כל ההוצאות'!$F:$F,"יולי 2026") | AB14: =SUMIFS('כל ההוצאות'!$D:$D,'כל ההוצאות'!$B:$B,"Higgsfield",'כל ההוצאות'!$F:$F,"אוגוסט 2026") | AC14: =SUMIFS('כל ההוצאות'!$E:$E,'כל ההוצאות'!$B:$B,"Higgsfield",'כל ההוצאות'!$F:$F,"אוגוסט 2026") | AD14: =SUMIFS('כל ההוצאות'!$D:$D,'כל ההוצאות'!$B:$B,"Higgsfield",'כל ההוצאות'!$F:$F,"ספטמבר 2026") | AE14: =SUMIFS('כל ההוצאות'!$E:$E,'כל ההוצאות'!$B:$B,"Higgsfield",'כל ההוצאות'!$F:$F,"ספטמבר 2026") | AF14: =SUMIFS('כל ההוצאות'!$D:$D,'כל ההוצאות'!$B:$B,"Higgsfield",'כל ההוצאות'!$F:$F,"אוקטובר 2026") | AG14: =SUMIFS('כל ההוצאות'!$E:$E,'כל ההוצאות'!$B:$B,"Higgsfield",'כל ההוצאות'!$F:$F,"אוקטובר 2026") | AH14: =SUMIFS('כל ההוצאות'!$D:$D,'כל ההוצאות'!$B:$B,"Higgsfield",'כל ההוצאות'!$F:$F,"נובמבר 2026") | AI14: =SUMIFS('כל ההוצאות'!$E:$E,'כל ההוצאות'!$B:$B,"Higgsfield",'כל ההוצאות'!$F:$F,"נובמבר 2026") | AJ14: =SUMIFS('כל ההוצאות'!$D:$D,'כל ההוצאות'!$B:$B,"Higgsfield",'כל ההוצאות'!$F:$F,"דצמבר 2026") | AK14: =SUMIFS('כל ההוצאות'!$E:$E,'כל ההוצאות'!$B:$B,"Higgsfield",'כל ההוצאות'!$F:$F,"דצמבר 2026") | AL14: =SUM(B14,D14,F14,H14,J14,L14,N14,P14,R14,T14,V14,X14,Z14,AB14,AD14,AF14,AH14,AJ14) | AM14: =SUM(C14,E14,G14,I14,K14,M14,O14,Q14,S14,U14,W14,Y14,AA14,AC14,AE14,AG14,AI14,AK14)
A15: IONOS | B15: =SUMIFS('כל ההוצאות'!$D:$D,'כל ההוצאות'!$B:$B,"IONOS",'כל ההוצאות'!$F:$F,"יולי 2025") | C15: =SUMIFS('כל ההוצאות'!$E:$E,'כל ההוצאות'!$B:$B,"IONOS",'כל ההוצאות'!$F:$F,"יולי 2025") | D15: =SUMIFS('כל ההוצאות'!$D:$D,'כל ההוצאות'!$B:$B,"IONOS",'כל ההוצאות'!$F:$F,"אוגוסט 2025") | E15: =SUMIFS('כל ההוצאות'!$E:$E,'כל ההוצאות'!$B:$B,"IONOS",'כל ההוצאות'!$F:$F,"אוגוסט 2025") | F15: =SUMIFS('כל ההוצאות'!$D:$D,'כל ההוצאות'!$B:$B,"IONOS",'כל ההוצאות'!$F:$F,"ספטמבר 2025") | G15: =SUMIFS('כל ההוצאות'!$E:$E,'כל ההוצאות'!$B:$B,"IONOS",'כל ההוצאות'!$F:$F,"ספטמבר 2025") | H15: =SUMIFS('כל ההוצאות'!$D:$D,'כל ההוצאות'!$B:$B,"IONOS",'כל ההוצאות'!$F:$F,"אוקטובר 2025") | I15: =SUMIFS('כל ההוצאות'!$E:$E,'כל ההוצאות'!$B:$B,"IONOS",'כל ההוצאות'!$F:$F,"אוקטובר 2025") | J15: =SUMIFS('כל ההוצאות'!$D:$D,'כל ההוצאות'!$B:$B,"IONOS",'כל ההוצאות'!$F:$F,"נובמבר 2025") | K15: =SUMIFS('כל ההוצאות'!$E:$E,'כל ההוצאות'!$B:$B,"IONOS",'כל ההוצאות'!$F:$F,"נובמבר 2025") | L15: =SUMIFS('כל ההוצאות'!$D:$D,'כל ההוצאות'!$B:$B,"IONOS",'כל ההוצאות'!$F:$F,"דצמבר 2025") | M15: =SUMIFS('כל ההוצאות'!$E:$E,'כל ההוצאות'!$B:$B,"IONOS",'כל ההוצאות'!$F:$F,"דצמבר 2025") | N15: =SUMIFS('כל ההוצאות'!$D:$D,'כל ההוצאות'!$B:$B,"IONOS",'כל ההוצאות'!$F:$F,"ינואר 2026") | O15: =SUMIFS('כל ההוצאות'!$E:$E,'כל ההוצאות'!$B:$B,"IONOS",'כל ההוצאות'!$F:$F,"ינואר 2026") | P15: =SUMIFS('כל ההוצאות'!$D:$D,'כל ההוצאות'!$B:$B,"IONOS",'כל ההוצאות'!$F:$F,"פברואר 2026") | Q15: =SUMIFS('כל ההוצאות'!$E:$E,'כל ההוצאות'!$B:$B,"IONOS",'כל ההוצאות'!$F:$F,"פברואר 2026") | R15: =SUMIFS('כל ההוצאות'!$D:$D,'כל ההוצאות'!$B:$B,"IONOS",'כל ההוצאות'!$F:$F,"מרץ 2026") | S15: =SUMIFS('כל ההוצאות'!$E:$E,'כל ההוצאות'!$B:$B,"IONOS",'כל ההוצאות'!$F:$F,"מרץ 2026") | T15: =SUMIFS('כל ההוצאות'!$D:$D,'כל ההוצאות'!$B:$B,"IONOS",'כל ההוצאות'!$F:$F,"אפריל 2026") | U15: =SUMIFS('כל ההוצאות'!$E:$E,'כל ההוצאות'!$B:$B,"IONOS",'כל ההוצאות'!$F:$F,"אפריל 2026") | V15: =SUMIFS('כל ההוצאות'!$D:$D,'כל ההוצאות'!$B:$B,"IONOS",'כל ההוצאות'!$F:$F,"מאי 2026") | W15: =SUMIFS('כל ההוצאות'!$E:$E,'כל ההוצאות'!$B:$B,"IONOS",'כל ההוצאות'!$F:$F,"מאי 2026") | X15: =SUMIFS('כל ההוצאות'!$D:$D,'כל ההוצאות'!$B:$B,"IONOS",'כל ההוצאות'!$F:$F,"יוני 2026") | Y15: =SUMIFS('כל ההוצאות'!$E:$E,'כל ההוצאות'!$B:$B,"IONOS",'כל ההוצאות'!$F:$F,"יוני 2026") | Z15: =SUMIFS('כל ההוצאות'!$D:$D,'כל ההוצאות'!$B:$B,"IONOS",'כל ההוצאות'!$F:$F,"יולי 2026") | AA15: =SUMIFS('כל ההוצאות'!$E:$E,'כל ההוצאות'!$B:$B,"IONOS",'כל ההוצאות'!$F:$F,"יולי 2026") | AB15: =SUMIFS('כל ההוצאות'!$D:$D,'כל ההוצאות'!$B:$B,"IONOS",'כל ההוצאות'!$F:$F,"אוגוסט 2026") | AC15: =SUMIFS('כל ההוצאות'!$E:$E,'כל ההוצאות'!$B:$B,"IONOS",'כל ההוצאות'!$F:$F,"אוגוסט 2026") | AD15: =SUMIFS('כל ההוצאות'!$D:$D,'כל ההוצאות'!$B:$B,"IONOS",'כל ההוצאות'!$F:$F,"ספטמבר 2026") | AE15: =SUMIFS('כל ההוצאות'!$E:$E,'כל ההוצאות'!$B:$B,"IONOS",'כל ההוצאות'!$F:$F,"ספטמבר 2026") | AF15: =SUMIFS('כל ההוצאות'!$D:$D,'כל ההוצאות'!$B:$B,"IONOS",'כל ההוצאות'!$F:$F,"אוקטובר 2026") | AG15: =SUMIFS('כל ההוצאות'!$E:$E,'כל ההוצאות'!$B:$B,"IONOS",'כל ההוצאות'!$F:$F,"אוקטובר 2026") | AH15: =SUMIFS('כל ההוצאות'!$D:$D,'כל ההוצאות'!$B:$B,"IONOS",'כל ההוצאות'!$F:$F,"נובמבר 2026") | AI15: =SUMIFS('כל ההוצאות'!$E:$E,'כל ההוצאות'!$B:$B,"IONOS",'כל ההוצאות'!$F:$F,"נובמבר 2026") | AJ15: =SUMIFS('כל ההוצאות'!$D:$D,'כל ההוצאות'!$B:$B,"IONOS",'כל ההוצאות'!$F:$F,"דצמבר 2026") | AK15: =SUMIFS('כל ההוצאות'!$E:$E,'כל ההוצאות'!$B:$B,"IONOS",'כל ההוצאות'!$F:$F,"דצמבר 2026") | AL15: =SUM(B15,D15,F15,H15,J15,L15,N15,P15,R15,T15,V15,X15,Z15,AB15,AD15,AF15,AH15,AJ15) | AM15: =SUM(C15,E15,G15,I15,K15,M15,O15,Q15,S15,U15,W15,Y15,AA15,AC15,AE15,AG15,AI15,AK15)
